Workbook

Sheet 00_Report
A1: Wloclawek - Waste-to-Energy Project Dashboard Report
A2: Generato: 2026-05-14 14:26 | E2: Budget: Budget.xlsm
A3: Report aggiornato al momento del download: i dati derivano dai file Excel presenti in data/current.
A5: KPI | B5: Value | C5: KPI | D5: Value | M5: baseline_direct | N5: 501457853
A6: Costi diretti | B6: =N5 | C6: Budget attuale (col. AB) | D6: =N6 | M6: updated_direct | N6: 5.0145785e+08
A7: Costi indiretti | B7: =N7 | C7: Delta % | D7: =N8 | M7: baseline_indirect | N7: 40355205
A8: Costi garanzia, difetti, imprevisti: | B8: =N9 | C8: Costi garanzia, difetti, imprevisti: | D8: =N10 | M8: updated_indirect | N8: 40358717
A9: Ricavi base | B9: =N11 | C9: Ricavi base | D9: =N12 | M9: baseline_contingency | N9: 22098535
A10: Margine | B10: =N13 | C10: Margine | D10: =N14 | M10: updated_contingency | N10: 22098535
A11: Ordini chiusi ultimi 3 mesi | B11: =COUNTIF('04_Orders_3M'!$A:$A,"Closed last 3 months") | C11: Prossimi ordini 3 mesi | D11: =COUNTIF('04_Orders_3M'!$A:$A,"Next orders 3 months") | M11: baseline_revenue | N11: 627086000
A12: Milestones penalizzate | B12: =MAX(COUNTA('03_Milestones'!$B$7:$B$200)-COUNTIF('03_Milestones'!$B$7:$B$200,"Nessun dato disponibile"),0) | C12: Da ordinare / Planned | D12: =SUMIF('05_Status_Mix'!$A:$A,"Da ordinare",'05_Status_Mix'!$C:$C) | M12: updated_revenue | N12: 627086000
M13: baseline_margin | N13: 63174407
M14: updated_margin | N14: 63170895
M15: baseline_pct_costs | N15: 0
A16: Curva S degli ordini rispetto al pianificato | J16: Totale ordinato / da ordinare / negoziazione | M16: updated_pct_costs | N16: =IFERROR(N14/N10,0)

Sheet 01_Budget_Delta
A1: Budget Delta - Totale e WBS
A2: I dati sono linkati al foglio 07_Source_Budget_Delta. Budget 0 = colonna I del Budget; Budget attuale = colonna AB; Delta AB-I e Delta % sono formule.
A5: Budget 0 - col. I | B5: Budget attuale - col. AB | C5: Delta AB-I | D5: Delta %
A6: ='07_Source_Budget_Delta'!B7 | B6: ='07_Source_Budget_Delta'!B8 | C6: =B6-A6 | D6: =IFERROR(C6/A6,0)
A9: Section | B9: WBS | C9: Description PL | D9: Description EN | E9: Budget 0 - col. I | F9: Budget attuale - col. AB | G9: Delta AB-I | H9: Delta %
A10: ='07_Source_Budget_Delta'!A12 | B10: ='07_Source_Budget_Delta'!B12 | C10: ='07_Source_Budget_Delta'!C12 | D10: ='07_Source_Budget_Delta'!D12 | E10: ='07_Source_Budget_Delta'!E12 | F10: ='07_Source_Budget_Delta'!F12 | G10: =F10-E10 | H10: =IFERROR(G10/E10,0)
A11: ='07_Source_Budget_Delta'!A13 | B11: ='07_Source_Budget_Delta'!B13 | C11: ='07_Source_Budget_Delta'!C13 | D11: ='07_Source_Budget_Delta'!D13 | E11: ='07_Source_Budget_Delta'!E13 | F11: ='07_Source_Budget_Delta'!F13 | G11: =F11-E11 | H11: =IFERROR(G11/E11,0)
A12: ='07_Source_Budget_Delta'!A14 | B12: ='07_Source_Budget_Delta'!B14 | C12: ='07_Source_Budget_Delta'!C14 | D12: ='07_Source_Budget_Delta'!D14 | E12: ='07_Source_Budget_Delta'!E14 | F12: ='07_Source_Budget_Delta'!F14 | G12: =F12-E12 | H12: =IFERROR(G12/E12,0)
A13: ='07_Source_Budget_Delta'!A15 | B13: ='07_Source_Budget_Delta'!B15 | C13: ='07_Source_Budget_Delta'!C15 | D13: ='07_Source_Budget_Delta'!D15 | E13: ='07_Source_Budget_Delta'!E15 | F13: ='07_Source_Budget_Delta'!F15 | G13: =F13-E13 | H13: =IFERROR(G13/E13,0)
A14: ='07_Source_Budget_Delta'!A16 | B14: ='07_Source_Budget_Delta'!B16 | C14: ='07_Source_Budget_Delta'!C16 | D14: ='07_Source_Budget_Delta'!D16 | E14: ='07_Source_Budget_Delta'!E16 | F14: ='07_Source_Budget_Delta'!F16 | G14: =F14-E14 | H14: =IFERROR(G14/E14,0)
A15: ='07_Source_Budget_Delta'!A17 | B15: ='07_Source_Budget_Delta'!B17 | C15: ='07_Source_Budget_Delta'!C17 | D15: ='07_Source_Budget_Delta'!D17 | E15: ='07_Source_Budget_Delta'!E17 | F15: ='07_Source_Budget_Delta'!F17 | G15: =F15-E15 | H15: =IFERROR(G15/E15,0)
A16: ='07_Source_Budget_Delta'!A18 | B16: ='07_Source_Budget_Delta'!B18 | C16: ='07_Source_Budget_Delta'!C18 | D16: ='07_Source_Budget_Delta'!D18 | E16: ='07_Source_Budget_Delta'!E18 | F16: ='07_Source_Budget_Delta'!F18 | G16: =F16-E16 | H16: =IFERROR(G16/E16,0)
A17: ='07_Source_Budget_Delta'!A19 | B17: ='07_Source_Budget_Delta'!B19 | C17: ='07_Source_Budget_Delta'!C19 | D17: ='07_Source_Budget_Delta'!D19 | E17: ='07_Source_Budget_Delta'!E19 | F17: ='07_Source_Budget_Delta'!F19 | G17: =F17-E17 | H17: =IFERROR(G17/E17,0)
A18: ='07_Source_Budget_Delta'!A20 | B18: ='07_Source_Budget_Delta'!B20 | C18: ='07_Source_Budget_Delta'!C20 | D18: ='07_Source_Budget_Delta'!D20 | E18: ='07_Source_Budget_Delta'!E20 | F18: ='07_Source_Budget_Delta'!F20 | G18: =F18-E18 | H18: =IFERROR(G18/E18,0)
A19: ='07_Source_Budget_Delta'!A21 | B19: ='07_Source_Budget_Delta'!B21 | C19: ='07_Source_Budget_Delta'!C21 | D19: ='07_Source_Budget_Delta'!D21 | E19: ='07_Source_Budget_Delta'!E21 | F19: ='07_Source_Budget_Delta'!F21 | G19: =F19-E19 | H19: =IFERROR(G19/E19,0)
A20: ='07_Source_Budget_Delta'!A22 | B20: ='07_Source_Budget_Delta'!B22 | C20: ='07_Source_Budget_Delta'!C22 | D20: ='07_Source_Budget_Delta'!D22 | E20: ='07_Source_Budget_Delta'!E22 | F20: ='07_Source_Budget_Delta'!F22 | G20: =F20-E20 | H20: =IFERROR(G20/E20,0)
A21: ='07_Source_Budget_Delta'!A23 | B21: ='07_Source_Budget_Delta'!B23 | C21: ='07_Source_Budget_Delta'!C23 | D21: ='07_Source_Budget_Delta'!D23 | E21: ='07_Source_Budget_Delta'!E23 | F21: ='07_Source_Budget_Delta'!F23 | G21: =F21-E21 | H21: =IFERROR(G21/E21,0)
... A35: ='07_Source_Budget_Delta'!A37 | B35: ='07_Source_Budget_Delta'!B37 | C35: ='07_Source_Budget_Delta'!C37 | D35: ='07_Source_Budget_Delta'!D37 | E35: ='07_Source_Budget_Delta'!E37 | F35: ='07_Source_Budget_Delta'!F37 | G35: =F35-E35 | H35: =IFERROR(G35/E35,0)

Sheet 02_PORR_Production
A1: Month | B1: PORR declared production / Budget monthly | C1: Cumulative
A2: ='08_Source_PORR_Production'!A7 | B2: ='08_Source_PORR_Production'!B7 | C2: =SUM($B$2:B2)
A3: ='08_Source_PORR_Production'!A8 | B3: ='08_Source_PORR_Production'!B8 | C3: =SUM($B$2:B3)
A4: ='08_Source_PORR_Production'!A9 | B4: ='08_Source_PORR_Production'!B9 | C4: =SUM($B$2:B4)
A5: ='08_Source_PORR_Production'!A10 | B5: ='08_Source_PORR_Production'!B10 | C5: =SUM($B$2:B5)
A6: ='08_Source_PORR_Production'!A11 | B6: ='08_Source_PORR_Production'!B11 | C6: =SUM($B$2:B6)
A7: ='08_Source_PORR_Production'!A12 | B7: ='08_Source_PORR_Production'!B12 | C7: =SUM($B$2:B7)
A8: ='08_Source_PORR_Production'!A13 | B8: ='08_Source_PORR_Production'!B13 | C8: =SUM($B$2:B8)
A9: ='08_Source_PORR_Production'!A14 | B9: ='08_Source_PORR_Production'!B14 | C9: =SUM($B$2:B9)
A10: ='08_Source_PORR_Production'!A15 | B10: ='08_Source_PORR_Production'!B15 | C10: =SUM($B$2:B10)
A11: ='08_Source_PORR_Production'!A16 | B11: ='08_Source_PORR_Production'!B16 | C11: =SUM($B$2:B11)
A12: ='08_Source_PORR_Production'!A17 | B12: ='08_Source_PORR_Production'!B17 | C12: =SUM($B$2:B12)
A13: ='08_Source_PORR_Production'!A18 | B13: ='08_Source_PORR_Production'!B18 | C13: =SUM($B$2:B13)
... A38: ='08_Source_PORR_Production'!A43 | B38: ='08_Source_PORR_Production'!B43 | C38: =SUM($B$2:B38)
A41: Year | B41: Annual total declared
A42: 2025 | B42: =SUMIFS($B$2:$B$38,$A$2:$A$38,"*2025*")
A43: 2026 | B43: =SUMIFS($B$2:$B$38,$A$2:$A$38,"*2026*")
A44: 2027 | B44: =SUMIFS($B$2:$B$38,$A$2:$A$38,"*2027*")
A45: 2028 | B45: =SUMIFS($B$2:$B$38,$A$2:$A$38,"*2028*")

Sheet 03_Milestones
A1: Nota logica
A2: Le milestone qui riportate sono considerate “penalizzate” perché sono classificate nella sezione “Milestones penalizzate” del file Programma Wloclawek_Milestones.xlsx. Non è un calcolo automatico della penale scattata: indica milestone contrattualmente soggette a penale / penalizzabili.
A6: No. | B6: Milestone | C6: Start date | D6: Finish date
A7: 1 | B7: Water pressure test | C7: 46676 | D7: 46676
A8: 2 | B8: Placement of the turbo-generator on the foundation | C8: 46646 | D8: 46646
A9: 3 | B9: Measurement of guaranteed parameters A | C9: 46927 | D9: 46927
A10: 4 | B10: Handover of the ITPO project to operation | C10: 46934 | D10: 46934

Sheet 04_Orders_3M
A1: Type | B1: WBS | C1: Package | D1: Status | E1: Date | F1: Value | G1: Buyer
A2: ='10_Source_Orders_3M'!A2 | B2: ='10_Source_Orders_3M'!B2 | C2: ='10_Source_Orders_3M'!C2 | D2: ='10_Source_Orders_3M'!D2 | E2: ='10_Source_Orders_3M'!E2 | F2: ='10_Source_Orders_3M'!F2 | G2: ='10_Source_Orders_3M'!G2
A3: ='10_Source_Orders_3M'!A3 | B3: ='10_Source_Orders_3M'!B3 | C3: ='10_Source_Orders_3M'!C3 | D3: ='10_Source_Orders_3M'!D3 | E3: ='10_Source_Orders_3M'!E3 | F3: ='10_Source_Orders_3M'!F3 | G3: ='10_Source_Orders_3M'!G3
A4: ='10_Source_Orders_3M'!A4 | B4: ='10_Source_Orders_3M'!B4 | C4: ='10_Source_Orders_3M'!C4 | D4: ='10_Source_Orders_3M'!D4 | E4: ='10_Source_Orders_3M'!E4 | F4: ='10_Source_Orders_3M'!F4 | G4: ='10_Source_Orders_3M'!G4
A5: ='10_Source_Orders_3M'!A5 | B5: ='10_Source_Orders_3M'!B5 | C5: ='10_Source_Orders_3M'!C5 | D5: ='10_Source_Orders_3M'!D5 | E5: ='10_Source_Orders_3M'!E5 | F5: ='10_Source_Orders_3M'!F5 | G5: ='10_Source_Orders_3M'!G5
A6: ='10_Source_Orders_3M'!A6 | B6: ='10_Source_Orders_3M'!B6 | C6: ='10_Source_Orders_3M'!C6 | D6: ='10_Source_Orders_3M'!D6 | E6: ='10_Source_Orders_3M'!E6 | F6: ='10_Source_Orders_3M'!F6 | G6: ='10_Source_Orders_3M'!G6
A7: ='10_Source_Orders_3M'!A7 | B7: ='10_Source_Orders_3M'!B7 | C7: ='10_Source_Orders_3M'!C7 | D7: ='10_Source_Orders_3M'!D7 | E7: ='10_Source_Orders_3M'!E7 | F7: ='10_Source_Orders_3M'!F7 | G7: ='10_Source_Orders_3M'!G7
A8: ='10_Source_Orders_3M'!A8 | B8: ='10_Source_Orders_3M'!B8 | C8: ='10_Source_Orders_3M'!C8 | D8: ='10_Source_Orders_3M'!D8 | E8: ='10_Source_Orders_3M'!E8 | F8: ='10_Source_Orders_3M'!F8 | G8: ='10_Source_Orders_3M'!G8
A9: ='10_Source_Orders_3M'!A9 | B9: ='10_Source_Orders_3M'!B9 | C9: ='10_Source_Orders_3M'!C9 | D9: ='10_Source_Orders_3M'!D9 | E9: ='10_Source_Orders_3M'!E9 | F9: ='10_Source_Orders_3M'!F9 | G9: ='10_Source_Orders_3M'!G9
A10: ='10_Source_Orders_3M'!A10 | B10: ='10_Source_Orders_3M'!B10 | C10: ='10_Source_Orders_3M'!C10 | D10: ='10_Source_Orders_3M'!D10 | E10: ='10_Source_Orders_3M'!E10 | F10: ='10_Source_Orders_3M'!F10 | G10: ='10_Source_Orders_3M'!G10
A11: ='10_Source_Orders_3M'!A11 | B11: ='10_Source_Orders_3M'!B11 | C11: ='10_Source_Orders_3M'!C11 | D11: ='10_Source_Orders_3M'!D11 | E11: ='10_Source_Orders_3M'!E11 | F11: ='10_Source_Orders_3M'!F11 | G11: ='10_Source_Orders_3M'!G11
A12: ='10_Source_Orders_3M'!A12 | B12: ='10_Source_Orders_3M'!B12 | C12: ='10_Source_Orders_3M'!C12 | D12: ='10_Source_Orders_3M'!D12 | E12: ='10_Source_Orders_3M'!E12 | F12: ='10_Source_Orders_3M'!F12 | G12: ='10_Source_Orders_3M'!G12
A13: ='10_Source_Orders_3M'!A13 | B13: ='10_Source_Orders_3M'!B13 | C13: ='10_Source_Orders_3M'!C13 | D13: ='10_Source_Orders_3M'!D13 | E13: ='10_Source_Orders_3M'!E13 | F13: ='10_Source_Orders_3M'!F13 | G13: ='10_Source_Orders_3M'!G13
... A97: ='10_Source_Orders_3M'!A97 | B97: ='10_Source_Orders_3M'!B97 | C97: ='10_Source_Orders_3M'!C97 | D97: ='10_Source_Orders_3M'!D97 | E97: ='10_Source_Orders_3M'!E97 | F97: ='10_Source_Orders_3M'!F97 | G97: ='10_Source_Orders_3M'!G97

Sheet 05_Status_Mix
A1: Status group | B1: Count | C1: Value | D1: Percentage
A2: ='09_Source_Status_Mix'!A9 | B2: ='09_Source_Status_Mix'!B9 | C2: ='09_Source_Status_Mix'!C9 | D2: ='09_Source_Status_Mix'!D9
A3: ='09_Source_Status_Mix'!A10 | B3: ='09_Source_Status_Mix'!B10 | C3: ='09_Source_Status_Mix'!C10 | D3: ='09_Source_Status_Mix'!D10
A4: ='09_Source_Status_Mix'!A11 | B4: ='09_Source_Status_Mix'!B11 | C4: ='09_Source_Status_Mix'!C11 | D4: ='09_Source_Status_Mix'!D11

Sheet 06_S_Curve_Data
A1: Month | B1: Label | C1: Procurement monthly | D1: Procurement cumulative | E1: Budget monthly | F1: Budget cumulative | G1: Contracted monthly | H1: Contracted cumulative | I1: Current marker
A2: ='11_Source_S_Curve_Data'!A10 | B2: ='11_Source_S_Curve_Data'!B10 | C2: ='11_Source_S_Curve_Data'!C10 | D2: ='11_Source_S_Curve_Data'!D10 | E2: ='11_Source_S_Curve_Data'!E10 | F2: ='11_Source_S_Curve_Data'!F10 | G2: ='11_Source_S_Curve_Data'!G10 | H2: ='11_Source_S_Curve_Data'!H10 | I2: ='11_Source_S_Curve_Data'!I10
A3: ='11_Source_S_Curve_Data'!A11 | B3: ='11_Source_S_Curve_Data'!B11 | C3: ='11_Source_S_Curve_Data'!C11 | D3: ='11_Source_S_Curve_Data'!D11 | E3: ='11_Source_S_Curve_Data'!E11 | F3: ='11_Source_S_Curve_Data'!F11 | G3: ='11_Source_S_Curve_Data'!G11 | H3: ='11_Source_S_Curve_Data'!H11 | I3: ='11_Source_S_Curve_Data'!I11
A4: ='11_Source_S_Curve_Data'!A12 | B4: ='11_Source_S_Curve_Data'!B12 | C4: ='11_Source_S_Curve_Data'!C12 | D4: ='11_Source_S_Curve_Data'!D12 | E4: ='11_Source_S_Curve_Data'!E12 | F4: ='11_Source_S_Curve_Data'!F12 | G4: ='11_Source_S_Curve_Data'!G12 | H4: ='11_Source_S_Curve_Data'!H12 | I4: ='11_Source_S_Curve_Data'!I12
A5: ='11_Source_S_Curve_Data'!A13 | B5: ='11_Source_S_Curve_Data'!B13 | C5: ='11_Source_S_Curve_Data'!C13 | D5: ='11_Source_S_Curve_Data'!D13 | E5: ='11_Source_S_Curve_Data'!E13 | F5: ='11_Source_S_Curve_Data'!F13 | G5: ='11_Source_S_Curve_Data'!G13 | H5: ='11_Source_S_Curve_Data'!H13 | I5: ='11_Source_S_Curve_Data'!I13
A6: ='11_Source_S_Curve_Data'!A14 | B6: ='11_Source_S_Curve_Data'!B14 | C6: ='11_Source_S_Curve_Data'!C14 | D6: ='11_Source_S_Curve_Data'!D14 | E6: ='11_Source_S_Curve_Data'!E14 | F6: ='11_Source_S_Curve_Data'!F14 | G6: ='11_Source_S_Curve_Data'!G14 | H6: ='11_Source_S_Curve_Data'!H14 | I6: ='11_Source_S_Curve_Data'!I14
A7: ='11_Source_S_Curve_Data'!A15 | B7: ='11_Source_S_Curve_Data'!B15 | C7: ='11_Source_S_Curve_Data'!C15 | D7: ='11_Source_S_Curve_Data'!D15 | E7: ='11_Source_S_Curve_Data'!E15 | F7: ='11_Source_S_Curve_Data'!F15 | G7: ='11_Source_S_Curve_Data'!G15 | H7: ='11_Source_S_Curve_Data'!H15 | I7: ='11_Source_S_Curve_Data'!I15
A8: ='11_Source_S_Curve_Data'!A16 | B8: ='11_Source_S_Curve_Data'!B16 | C8: ='11_Source_S_Curve_Data'!C16 | D8: ='11_Source_S_Curve_Data'!D16 | E8: ='11_Source_S_Curve_Data'!E16 | F8: ='11_Source_S_Curve_Data'!F16 | G8: ='11_Source_S_Curve_Data'!G16 | H8: ='11_Source_S_Curve_Data'!H16 | I8: ='11_Source_S_Curve_Data'!I16
A9: ='11_Source_S_Curve_Data'!A17 | B9: ='11_Source_S_Curve_Data'!B17 | C9: ='11_Source_S_Curve_Data'!C17 | D9: ='11_Source_S_Curve_Data'!D17 | E9: ='11_Source_S_Curve_Data'!E17 | F9: ='11_Source_S_Curve_Data'!F17 | G9: ='11_Source_S_Curve_Data'!G17 | H9: ='11_Source_S_Curve_Data'!H17 | I9: ='11_Source_S_Curve_Data'!I17
A10: ='11_Source_S_Curve_Data'!A18 | B10: ='11_Source_S_Curve_Data'!B18 | C10: ='11_Source_S_Curve_Data'!C18 | D10: ='11_Source_S_Curve_Data'!D18 | E10: ='11_Source_S_Curve_Data'!E18 | F10: ='11_Source_S_Curve_Data'!F18 | G10: ='11_Source_S_Curve_Data'!G18 | H10: ='11_Source_S_Curve_Data'!H18 | I10: ='11_Source_S_Curve_Data'!I18
A11: ='11_Source_S_Curve_Data'!A19 | B11: ='11_Source_S_Curve_Data'!B19 | C11: ='11_Source_S_Curve_Data'!C19 | D11: ='11_Source_S_Curve_Data'!D19 | E11: ='11_Source_S_Curve_Data'!E19 | F11: ='11_Source_S_Curve_Data'!F19 | G11: ='11_Source_S_Curve_Data'!G19 | H11: ='11_Source_S_Curve_Data'!H19 | I11: ='11_Source_S_Curve_Data'!I19
A12: ='11_Source_S_Curve_Data'!A20 | B12: ='11_Source_S_Curve_Data'!B20 | C12: ='11_Source_S_Curve_Data'!C20 | D12: ='11_Source_S_Curve_Data'!D20 | E12: ='11_Source_S_Curve_Data'!E20 | F12: ='11_Source_S_Curve_Data'!F20 | G12: ='11_Source_S_Curve_Data'!G20 | H12: ='11_Source_S_Curve_Data'!H20 | I12: ='11_Source_S_Curve_Data'!I20
A13: ='11_Source_S_Curve_Data'!A21 | B13: ='11_Source_S_Curve_Data'!B21 | C13: ='11_Source_S_Curve_Data'!C21 | D13: ='11_Source_S_Curve_Data'!D21 | E13: ='11_Source_S_Curve_Data'!E21 | F13: ='11_Source_S_Curve_Data'!F21 | G13: ='11_Source_S_Curve_Data'!G21 | H13: ='11_Source_S_Curve_Data'!H21 | I13: ='11_Source_S_Curve_Data'!I21
... A38: ='11_Source_S_Curve_Data'!A46 | B38: ='11_Source_S_Curve_Data'!B46 | C38: ='11_Source_S_Curve_Data'!C46 | D38: ='11_Source_S_Curve_Data'!D46 | E38: ='11_Source_S_Curve_Data'!E46 | F38: ='11_Source_S_Curve_Data'!F46 | G38: ='11_Source_S_Curve_Data'!G46 | H38: ='11_Source_S_Curve_Data'!H46 | I38: ='11_Source_S_Curve_Data'!I46

Sheet 07_Source_Budget_Delta
A1: Nota origine dati
A2: Dati estratti dal file Budget in data/current: Budget.xlsm, sheet Włocławek Budget. Totale Budget 0 = cella I12; Budget attuale = cella AB12. La tabella WBS sotto riporta le righe top-level trovate in colonna A: WBS 1-8 della sezione costi diretti e WBS 1-17 della sezione riepilogo/finanziaria. I valori Budget 0 e Budget attuale derivano rispettivamente dalle colonne I e AB; Delta e Delta % sono formule nel report.
A6: Metric | B6: Value | C6: Source file | D6: Source sheet | E6: Source cell
A7: Budget 0 - col. I | B7: 505343424 | C7: Budget.xlsm | D7: Włocławek Budget | E7: I12
A8: Budget attuale - col. AB | B8: 5.0145785e+08 | C8: Budget.xlsm | D8: Włocławek Budget | E8: AB12
A11: Section | B11: WBS | C11: Description PL | D11: Description EN | E11: Budget 0 - col. I | F11: Budget attuale - col. AB | G11: Delta AB-I | H11: Delta % | I11: Source row | J11: Source cells
A12: Direct cost / root budget group | B12: 1 | C12: PROJEKTOWANIE | D12: DESIGN | E12: 30550000 | F12: 27170000 | G12: =F12-E12 | H12: =IFERROR(G12/E12,0) | I12: 13 | J12: I13 / AB13
A13: Direct cost / root budget group | B13: 2 | C13: Roboty branży budowlano-konstrukcyjnej | D13: Civil works | E13: 113409768 | F13: 1.0810977e+08 | G13: =F13-E13 | H13: =IFERROR(G13/E13,0) | I13: 38 | J13: I38 / AB38
A14: Direct cost / root budget group | B14: 3 | C14: BRANŻA ELEKTRYCZNA | D14: ELECTRICAL WORKS | E14: 10912000 | F14: 58345340 | G14: =F14-E14 | H14: =IFERROR(G14/E14,0) | I14: 143 | J14: I143 / AB143
A15: Direct cost / root budget group | B15: 4 | C15: Roboty branży sanitarnej i ppoż | D15: Sanitary works and fire-fighting system | E15: 34223555 | F15: 21293319 | G15: =F15-E15 | H15: =IFERROR(G15/E15,0) | I15: 160 | J15: I160 / AB160
A16: Direct cost / root budget group | B16: 5 | C16: Roboty branży mechanicznej i technologicznej | D16: Mechanical and technological works | E16: 293798902 | F16: 2.5866665e+08 | G16: =F16-E16 | H16: =IFERROR(G16/E16,0) | I16: 185 | J16: I185 / AB185
A17: Direct cost / root budget group | B17: 6 | C17: Zimny i gorący rozruch, Ruch próbny instalacji technologicznych | D17: Cold and hot commissioning & Trial run of technological equipment | E17: 8499199 | F17: 8500000 | G17: =F17-E17 | H17: =IFERROR(G17/E17,0) | I17: 257 | J17: I257 / AB257
A18: Direct cost / root budget group | B18: 7 | C18: Wyrównanie do wartości z TCO / Rezerwa | D18: Alignment to TCO values / Backup | E18: 0 | F18: 538352 | G18: =F18-E18 | H18: =IFERROR(G18/E18,0) | I18: 276 | J18: I276 / AB276
A19: Direct cost / root budget group | B19: 8 | C19: Pozostałe koszty | E19: 0 | F19: 414429 | G19: =F19-E19 | H19: =IFERROR(G19/E19,0) | I19: 279 | J19: I279 / AB279
A20: Financial summary / WBS 1-17 | B20: 1 | C20: TKW | E20: 505757853 | F20: 5.0145785e+08 | G20: =F20-E20 | H20: =IFERROR(G20/E20,0) | I20: 283 | J20: I283 / AB283
A21: Financial summary / WBS 1-17 | B21: 1 | C21: PERSONEL | D21: STAFF | E21: 0 | F21: 0 | G21: =F21-E21 | H21: =IFERROR(G21/E21,0) | I21: 290 | J21: I290 / AB290
A22: Financial summary / WBS 1-17 | B22: 2 | C22: TKW Razem | D22: Direct + indirect costs | E22: 5.4614887e+08 | F22: 5.639151e+08 | G22: =F22-E22 | H22: =IFERROR(G22/E22,0) | I22: 428 | J22: I428 / AB428
A23: Financial summary / WBS 1-17 | B23: 3 | C23: Kwota narzutów kalkulacyjnych | E23: 85237133 | F23: 63170895 | G23: =F23-E23 | H23: =IFERROR(G23/E23,0) | I23: 429 | J23: I429 / AB429
A24: Financial summary / WBS 1-17 | B24: 4 | C24: % narzutów kalkulacyjnych | E24: 0.15606941 | F24: 0.112022 | G24: =F24-E24 | H24: =IFERROR(G24/E24,0) | I24: 430 | J24: I430 / AB430
A25: Financial summary / WBS 1-17 | B25: 5 | C25: Zlecenie otrzymane/Planowany przerób | E25: 631386000 | F25: 627086000 | G25: =F25-E25 | H25: =IFERROR(G25/E25,0) | I25: 440 | J25: I440 / AB440
A26: Financial summary / WBS 1-17 | B26: 6 | C26: Podwykonawstwo wewn. udzielone | E26: 0 | F26: 0 | G26: =F26-E26 | H26: =IFERROR(G26/E26,0) | I26: 441 | J26: I441 / AB441
A27: Financial summary / WBS 1-17 | B27: 7 | C27: Planowany Przerób po REGIE | D27: Planned capacity (REGIE) | E27: 631386000 | F27: 627086000 | G27: =F27-E27 | H27: =IFERROR(G27/E27,0) | I27: 442 | J27: I442 / AB442
A28: Financial summary / WBS 1-17 | B28: 8 | C28: Korekta kosztowa wpływająca tylko na wynik | E28: 0 | F28: 0 | G28: =F28-E28 | H28: =IFERROR(G28/E28,0) | I28: 445 | J28: I445 / AB445
A29: Financial summary / WBS 1-17 | B29: 9 | C29: Kwota narzutów kalkulacyjnych | E29: 85237133 | F29: 63170895 | G29: =F29-E29 | H29: =IFERROR(G29/E29,0) | I29: 446 | J29: I446 / AB446
A30: Financial summary / WBS 1-17 | B30: 10 | C30: Kwota narzutów kalkulacyjnych po korekcie | D30: Amount of imputed mark-ups after correction | E30: 0 | F30: 63170895 | G30: =F30-E30 | H30: =IFERROR(G30/E30,0) | I30: 447 | J30: I447 / AB447
A31: Financial summary / WBS 1-17 | B31: 11 | C31: Alokacje - REGIE | E31: 45080960 | F31: 31178096 | G31: =F31-E31 | H31: =IFERROR(G31/E31,0) | I31: 463 | J31: I463 / AB463
A32: Financial summary / WBS 1-17 | B32: 12 | C32: EBT w PLN - po uwzględnieniu REGIE | E32: 40156172 | F32: 31992799 | G32: =F32-E32 | H32: =IFERROR(G32/E32,0) | I32: 465 | J32: I465 / AB465
A33: Financial summary / WBS 1-17 | B33: 13 | C33: % EBT bez revaluation | E33: 0.063600036 | F33: 0.0510182 | G33: =F33-E33 | H33: =IFERROR(G33/E33,0) | I33: 466 | J33: I466 / AB466
A34: Financial summary / WBS 1-17 | B34: 14 | C34: EBT z Rewaluation | E34: 40156172 | F34: 54091334 | G34: =F34-E34 | H34: =IFERROR(G34/E34,0) | I34: 468 | J34: I468 / AB468
A35: Financial summary / WBS 1-17 | B35: 15 | C35: % EBT bez Contingency | E35: 0.063600036 | F35: 0.086258239 | G35: =F35-E35 | H35: =IFERROR(G35/E35,0) | I35: 469 | J35: I469 / AB469
A36: Financial summary / WBS 1-17 | B36: 16 | C36: Wartość robót wykonywanych przez konsorcjantów | E36: 0 | F36: 0 | G36: =F36-E36 | H36: =IFERROR(G36/E36,0) | I36: 476 | J36: I476 / AB476
A37: Financial summary / WBS 1-17 | B37: 17 | C37: Łączna wartość kontraktu (BBB + konsorcjanci) | E37: 631386000 | F37: 627086000 | G37: =F37-E37 | H37: =IFERROR(G37/E37,0) | I37: 477 | J37: I477 / AB477

Sheet 08_Source_PORR_Production
A1: Nota origine dati
A2: Dati estratti dal file Budget in data/current: Budget.xlsm, sheet Włocławek Budget. La produzione mensile dichiarata PORR / budget monthly deriva dalla riga 12, colonne AM:BW; le intestazioni mese sono sulla riga 11.
A6: Month | B6: Value | C6: Source cell | D6: Source header cell
A7: 2025-12-01 00:00:00 | B7: 6199140 | C7: AM12 | D7: AM11
A8: 2026-01-01 00:00:00 | B8: 1209845 | C8: AN12 | D8: AN11
A9: 2026-02-01 00:00:00 | B9: 4914057.8 | C9: AO12 | D9: AO11
A10: 2026-03-01 00:00:00 | B10: 5765471.9 | C10: AP12 | D10: AP11
A11: 2026-04-01 00:00:00 | B11: 6905734.1 | C11: AQ12 | D11: AQ11
A12: 2026-05-01 00:00:00 | B12: 8873827.1 | C12: AR12 | D12: AR11
A13: 2026-06-01 00:00:00 | B13: 10285632 | C13: AS12 | D13: AS11
A14: 2026-07-01 00:00:00 | B14: 10740382 | C14: AT12 | D14: AT11
A15: 2026-08-01 00:00:00 | B15: 11563023 | C15: AU12 | D15: AU11
A16: 2026-09-01 00:00:00 | B16: 16961089 | C16: AV12 | D16: AV11
A17: 2026-10-01 00:00:00 | B17: 20646902 | C17: AW12 | D17: AW11
A18: 2026-11-01 00:00:00 | B18: 16967268 | C18: AX12 | D18: AX11
... A43: 2028-12-01 00:00:00 | B43: 42828572 | C43: BW12 | D43: BW11

Sheet 09_Source_Status_Mix
A1: Nota origine e logica calcolo
A2: Dati derivati dal file Procurement in data/current, sheet Procurement Schedule. Colonne di riferimento: Q = stato procurement, S = Budget AK / budget aggiornato, T = valore contracted quando disponibile. Raggruppamento: Closed / Finalized / PCT approval = Ordinato; Planned = Da ordinare; tutti gli altri stati attivi = In negoziazione. Count = numero pacchetti nel gruppo; Value = somma economica del gruppo; Percentage = Value gruppo / totale Value dei tre gruppi.
A8: Status group | B8: Count | C8: Value | D8: Percentage
A9: Ordinato | B9: 83 | C9: 2.1866776e+08 | D9: =IFERROR(C9/SUM($C$9:$C$11),0)
A10: In negoziazione | B10: 50 | C10: 1.1414986e+08 | D10: =IFERROR(C10/SUM($C$9:$C$11),0)
A11: Da ordinare | B11: 199 | C11: 1.8720643e+08 | D11: =IFERROR(C11/SUM($C$9:$C$11),0)

Sheet 10_Source_Orders_3M
A1: Type | B1: WBS | C1: Package | D1: Status | E1: Date | F1: Value | G1: Buyer
A2: Closed last 3 months | B2: 8.2.11.1 | C2: TV ECd_33 | D2: closed | E2: 46064 | F2: 11980
A3: Closed last 3 months | B3: 8.7.1.5 | C3: Temporary Traffic Management ECd_34 | D3: closed | E3: 46064 | F3: 950
A4: Closed last 3 months | B4: 1.2.7.1 | C4: Preparation of an application for an integrated permit, together with all necessary documents. | D4: closed | E4: 46066 | F4: 113000
A5: Closed last 3 months | B5: 2.1 | C5: Foundation works | D5: closed | E5: 46068 | F5: 0
A6: Closed last 3 months | B6: 2.1.1 | C6: Diaphragm wall 100 cm thick and 6 adjacent barrettes | D6: closed | E6: 46068 | F6: 3176000 | G6: Jank Szczubiał
A7: Closed last 3 months | B7: 2.1.2 | C7: Slotted wall 100 cm thick and 6 berets | D7: closed | E7: 46068 | F7: 1124000 | G7: Jank Szczubiał
A8: Closed last 3 months | B8: 8.1.5 | C8: Stationary Cranes | D8: closed | E8: 46068 | F8: 0 | G8: Damian Gadowski
A9: Closed last 3 months | B9: 8.1.5.1 | C9: Stationary tower crane + self-erecting crane | D9: closed | E9: 46068 | F9: 1170200 | G9: Damian Gadowski
A10: Closed last 3 months | B10: 8.2.1.1 | C10: Office Space or Container Rental - Consortium's facility ECd_20 | D10: closed | E10: 46068 | F10: 821840 | G10: Urszula Szwarc
A11: Closed last 3 months | B11: 8.2.8.1 | C11: Cleaning services ECd_35 | D11: closed | E11: 46069 | F11: 178200
A12: Closed last 3 months | B12: 8.5.2.2 | C12: Office kitchen furniture ECd_36 | D12: closed | E12: 46070 | F12: 13414.64
A13: Closed last 3 months | B13: 8.5.1 | C13: Internet Connection ECd_37 | D13: closed | E13: 46073 | F13: 27350
A14: Closed last 3 months | B14: 8.1.3.3 | C14: Open order - sanitary industry assortment ECd_39 | D14: closed | E14: 46077 | F14: 30000
A15: Closed last 3 months | B15: 8.1.3.4 | C15: Open order - sanitary industry assortment ECd_40 | D15: closed | E15: 46077 | F15: 30000
A16: Closed last 3 months | B16: 5.4.1 | C16: Boiler - pressure parts | D16: PCT/approval | E16: 46081 | F16: 0 | G16: Roger Gołombek
A17: Closed last 3 months | B17: 5.4.1.1 | C17: Boiler - pressure parts | D17: PCT/approval | E17: 46081 | F17: 45990000 | G17: Roger Gołombek
A18: Closed last 3 months | B18: 8.4.1.1 | C18: Personal Occupational Health and Safety Equipment ECd_43 | D18: closed | E18: 46090 | F18: 30000
A19: Closed last 3 months | B19: 8.3.1.2 | C19: Generator rental ECd_44 | D19: closed | E19: 46096 | F19: 23904
A20: Closed last 3 months | B20: 8.7.1.6 | C20: Purchase of road signs ECd_42 | D20: closed | E20: 46096 | F20: 2000
A21: Closed last 3 months | B21: 8.7.1.7 | C21: Purchase of rubble for the construction of storage yards and work platforms ECd_45 | D21: closed | E21: 46096 | F21: 83200
A22: Closed last 3 months | B22: 2.11.5.3 | C22: Concrete slab installation on the ground | D22: closed | E22: 46106 | F22: 1735392.8 | G22: Agnieszka Zając
A23: Closed last 3 months | B23: 2.14.2.2 | C23: External road - aggregate delivery ECd_46 | D23: closed | E23: 46106 | F23: 134400 | G23: Agnieszka Zając
A24: Closed last 3 months | B24: 2.4.1 | C24: Insulation - work | D24: closed | E24: 46106 | F24: 733045.25 | G24: Agnieszka Zając
A25: Closed last 3 months | B25: 2.5.1.3 | C25: Construction of reinforced concrete foundations and underground structures | D25: closed | E25: 46106 | F25: 5276959.4 | G25: Agnieszka Zając
A26: Closed last 3 months | B26: 2.5.2.1 | C26: Reinforced concrete structure of the above-ground part of the B1 building - delivery and assembly of prefabricated elements | D26: closed | E26: 46106 | F26: 16616880 | G26: Jan Szczubiał
A27: Closed last 3 months | B27: 2.5.2.2.3 | C27: Reinforced concrete structure of the above-ground part of the B3 building - delivery and assembly of prefabricated elements | D27: closed | E27: 46106 | F27: 2115950 | G27: Jan Szczubiał
A28: Closed last 3 months | B28: 2.5.2.2.4 | C28: Reinforced concrete structure of the above-ground part of the other buildings | D28: closed | E28: 46106 | F28: 708072.75 | G28: Jan Szczubiał
A29: Closed last 3 months | B29: 2.6.2.1 | C29: Precast reinforced concrete structure of facility B3 (change from steel structure compared to the acquisition stage) | D29: closed | E29: 46106 | F29: 1004390 | G29: Robert Klimczak
A30: Closed last 3 months | B30: 2.6.3.1 | C30: Precast reinforced concrete structure of facility B4 (change from steel structure compared to the acquisition stage) | D30: closed | E30: 46106 | F30: 246780 | G30: Robert Klimczak
A31: Closed last 3 months | B31: 5.10.2 | C31: Auxiliary crane and hoists for the maintenance of the steam turbine | D31: PCT/approval | E31: 46115 | F31: 499000 | G31: Magdalena Białorucka
A32: Closed last 3 months | B32: 5.2.1 | C32: Overhead crane, grab and operator seat + Spare Grab | D32: PCT/approval | E32: 46115 | F32: 8701000 | G32: Magdalena Białorucka
A33: Closed last 3 months | B33: 2.14.2.1 | C33: External road- sub-base construction | D33: PCT/approval | E33: 46122 | F33: 250640 | G33: Agnieszka Zając
A34: Closed last 3 months | B34: 8.3.1.1 | C34: Electricity Costs | D34: PCT/approval | E34: 46122 | F34: 100000
A35: Closed last 3 months | B35: 8.7.1.4 | C35: Construction of aggregate squares | D35: PCT/approval | E35: 46122 | F35: 124700 | G35: Agnieszka Zając
A36: Closed last 3 months | B36: 8.8.4 | C36: Removing collisions related to site preparation and construction | D36: PCT/approval | E36: 46122 | F36: 50000
A37: Next orders 3 months | B37: 1.2.6 | C37: Piping and ducts design | D37: planned | E37: 46157 | F37: 2000000
A38: Next orders 3 months | B38: 1.2.6.2 | C38: Piping design | D38: planned | E38: 46157 | F38: 0
A39: Next orders 3 months | B39: 5.10.12 | C39: Stabilising pumps 2 x 100%, network pumps 3 x 50%, condensate pumps 2 x 100%, feed water pumps 3 pcs., cooling pumps | D39: planned | E39: 46157 | F39: 5517325 | G39: Stanisław Rucki
A40: Next orders 3 months | B40: 5.10.3 | C40: Air cooled condenser | D40: planned | E40: 46157 | F40: 9000000 | G40: Roger Gołombek
...

Sheet 11_Source_S_Curve_Data
A1: Nota origine e logica calcolo
A2: La Curva S deriva dal dashboard payload rigenerato dai file Excel in data/current. Procurement schedule cumulativo: somma mensile/cumulata dei valori Updated Budget / Budget AK del Procurement Schedule secondo le date procurement. Budget / programma cliente cumulativo: curva mensile/cumulata letta dal Budget, riga 12, colonne AM:BW. Ordini contrattualizzati cumulativo: somma mensile/cumulata dei valori Contracted secondo le date di chiusura/contrattualizzazione disponibili nel Procurement Schedule.
A9: Month | B9: Label | C9: Procurement monthly | D9: Procurement cumulative | E9: Budget monthly | F9: Budget cumulative | G9: Contracted monthly | H9: Contracted cumulative | I9: Current marker
A10: 2025-12 | B10: dic-2025 | C10: 6635951.4 | D10: 6635951.4 | E10: 6199140 | F10: 6199140 | G10: 0 | H10: 0
A11: 2026-01 | B11: gen-2026 | C11: 9407183.2 | D11: 16043135 | E11: 1209845 | F11: 7408985 | G11: 0 | H11: 0
A12: 2026-02 | B12: feb-2026 | C12: 28559502 | D12: 44602637 | E12: 7794586.9 | F12: 15203572 | G12: 0 | H12: 0
A13: 2026-03 | B13: mar-2026 | C13: 41783746 | D13: 86386383 | E13: 12423640 | F13: 27627212 | G13: 0 | H13: 0
A14: 2026-04 | B14: apr-2026 | C14: 41368004 | D14: 1.2775439e+08 | E14: 11336449 | F14: 38963661 | G14: 0 | H14: 0
A15: 2026-05 | B15: mag-2026 | C15: 39534318 | D15: 1.672887e+08 | E15: 13624888 | F15: 52588549 | G15: 0 | H15: 0 | I15: Current
A16: 2026-06 | B16: giu-2026 | C16: 38328273 | D16: 2.0561698e+08 | E16: 14910518 | F16: 67499067 | G16: 0 | H16: 0
A17: 2026-07 | B17: lug-2026 | C17: 37965907 | D17: 2.4358288e+08 | E17: 15028246 | F17: 82527313 | G17: 0 | H17: 0
A18: 2026-08 | B18: ago-2026 | C18: 28948794 | D18: 2.7253168e+08 | E18: 24539477 | F18: 1.0706679e+08 | G18: 0 | H18: 0
A19: 2026-09 | B19: set-2026 | C19: 29770985 | D19: 3.0230266e+08 | E19: 31216463 | F19: 1.3828325e+08 | G19: 0 | H19: 0
A20: 2026-10 | B20: ott-2026 | C20: 24376568 | D20: 3.2667923e+08 | E20: 27608193 | F20: 1.6589145e+08 | G20: 0 | H20: 0
A21: 2026-11 | B21: nov-2026 | C21: 42520041 | D21: 3.6919927e+08 | E21: 26540967 | F21: 1.9243241e+08 | G21: 0 | H21: 0
A22: 2026-12 | B22: dic-2026 | C22: 28741079 | D22: 3.9794035e+08 | E22: 28846792 | F22: 2.2127921e+08 | G22: 0 | H22: 0
A23: 2027-01 | B23: gen-2027 | C23: 15761647 | D23: 4.13702e+08 | E23: 27022581 | F23: 2.4830179e+08 | G23: 0 | H23: 0
A24: 2027-02 | B24: feb-2027 | C24: 15778130 | D24: 4.2948013e+08 | E24: 28325747 | F24: 2.7662753e+08 | G24: 0 | H24: 0
A25: 2027-03 | B25: mar-2027 | C25: 16128130 | D25: 4.4560826e+08 | E25: 35039986 | F25: 3.1166752e+08 | G25: 0 | H25: 0
A26: 2027-04 | B26: apr-2027 | C26: 14020661 | D26: 4.5962892e+08 | E26: 33822381 | F26: 3.454899e+08 | G26: 0 | H26: 0
A27: 2027-05 | B27: mag-2027 | C27: 6947735.9 | D27: 4.6657665e+08 | E27: 25897922 | F27: 3.7138782e+08 | G27: 0 | H27: 0
... A46: 2028-12 | B46: dic-2028 | C46: 0 | D46: 5.1936587e+08 | E46: 0 | F46: 4.9997369e+08 | G46: 0 | H46: 0
