Workbook

Sheet 00_Report
A1: Wloclawek - Waste-to-Energy Project Dashboard Report
A2: Generato: 2026-05-22 07:44 | E2: Budget: Budget.xlsm
A3: Report aggiornato al momento del download: i dati derivano dai file Excel presenti in data/current.
A5: KPI | B5: Value | C5: KPI | D5: Value | M5: baseline_direct | N5: 501457853
A6: Costi diretti | B6: =N5 | C6: Budget attuale (col. AB) | D6: =N6 | M6: updated_direct | N6: 5.0145785e+08
A7: Costi indiretti | B7: =N7 | C7: Delta % | D7: =N8 | M7: baseline_indirect | N7: 40355205
A8: Costi garanzia, difetti, imprevisti: | B8: =N9 | C8: Costi garanzia, difetti, imprevisti: | D8: =N10 | M8: updated_indirect | N8: 40036817
A9: Ricavi base | B9: =N11 | C9: Ricavi base | D9: =N12 | M9: baseline_contingency | N9: 22098535
A10: Margine | B10: =N13 | C10: Margine | D10: =N14 | M10: updated_contingency | N10: 22098535
A11: Ordini chiusi ultimi 3 mesi | B11: =COUNTIF('04_Orders_3M'!$A:$A,"Closed last 3 months") | C11: Prossimi ordini 3 mesi | D11: =COUNTIF('04_Orders_3M'!$A:$A,"Next orders 3 months") | M11: baseline_revenue | N11: 627086000
A12: Milestones penalizzate | B12: =MAX(COUNTA('03_Milestones'!$B$7:$B$200)-COUNTIF('03_Milestones'!$B$7:$B$200,"Nessun dato disponibile"),0) | C12: Da ordinare / Planned | D12: =SUMIF('05_Status_Mix'!$A:$A,"Da ordinare",'05_Status_Mix'!$C:$C) | M12: updated_revenue | N12: 627086000
M13: baseline_margin | N13: 63174407
M14: updated_margin | N14: 63492795
M15: baseline_pct_costs | N15: 0
A16: Curva S degli ordini rispetto al pianificato | J16: Mix ordini diretti - valore e numero pacchetti | M16: updated_pct_costs | N16: =IFERROR(N14/N10,0)

Sheet 01_Budget_Delta
A1: Budget Delta - Totale e WBS
A2: I dati sono linkati al foglio 07_Source_Budget_Delta. Budget 0 = colonna I del Budget; Budget attuale = colonna AB; Delta AB-I e Delta % sono formule.
A5: Budget 0 - col. I | B5: Budget attuale - col. AB | C5: Delta AB-I | D5: Delta %
A6: ='07_Source_Budget_Delta'!B7 | B6: ='07_Source_Budget_Delta'!B8 | C6: =B6-A6 | D6: =IFERROR(C6/A6,0)
A9: Section | B9: WBS | C9: Description PL | D9: Description EN | E9: Budget 0 - col. I | F9: Budget attuale - col. AB | G9: Delta AB-I | H9: Delta %
A10: ='07_Source_Budget_Delta'!A12 | B10: ='07_Source_Budget_Delta'!B12 | C10: ='07_Source_Budget_Delta'!C12 | D10: ='07_Source_Budget_Delta'!D12 | E10: ='07_Source_Budget_Delta'!E12 | F10: ='07_Source_Budget_Delta'!F12 | G10: =F10-E10 | H10: =IFERROR(G10/E10,0)
A11: ='07_Source_Budget_Delta'!A13 | B11: ='07_Source_Budget_Delta'!B13 | C11: ='07_Source_Budget_Delta'!C13 | D11: ='07_Source_Budget_Delta'!D13 | E11: ='07_Source_Budget_Delta'!E13 | F11: ='07_Source_Budget_Delta'!F13 | G11: =F11-E11 | H11: =IFERROR(G11/E11,0)
A12: ='07_Source_Budget_Delta'!A14 | B12: ='07_Source_Budget_Delta'!B14 | C12: ='07_Source_Budget_Delta'!C14 | D12: ='07_Source_Budget_Delta'!D14 | E12: ='07_Source_Budget_Delta'!E14 | F12: ='07_Source_Budget_Delta'!F14 | G12: =F12-E12 | H12: =IFERROR(G12/E12,0)
A13: ='07_Source_Budget_Delta'!A15 | B13: ='07_Source_Budget_Delta'!B15 | C13: ='07_Source_Budget_Delta'!C15 | D13: ='07_Source_Budget_Delta'!D15 | E13: ='07_Source_Budget_Delta'!E15 | F13: ='07_Source_Budget_Delta'!F15 | G13: =F13-E13 | H13: =IFERROR(G13/E13,0)
A14: ='07_Source_Budget_Delta'!A16 | B14: ='07_Source_Budget_Delta'!B16 | C14: ='07_Source_Budget_Delta'!C16 | D14: ='07_Source_Budget_Delta'!D16 | E14: ='07_Source_Budget_Delta'!E16 | F14: ='07_Source_Budget_Delta'!F16 | G14: =F14-E14 | H14: =IFERROR(G14/E14,0)
A15: ='07_Source_Budget_Delta'!A17 | B15: ='07_Source_Budget_Delta'!B17 | C15: ='07_Source_Budget_Delta'!C17 | D15: ='07_Source_Budget_Delta'!D17 | E15: ='07_Source_Budget_Delta'!E17 | F15: ='07_Source_Budget_Delta'!F17 | G15: =F15-E15 | H15: =IFERROR(G15/E15,0)
A16: ='07_Source_Budget_Delta'!A18 | B16: ='07_Source_Budget_Delta'!B18 | C16: ='07_Source_Budget_Delta'!C18 | D16: ='07_Source_Budget_Delta'!D18 | E16: ='07_Source_Budget_Delta'!E18 | F16: ='07_Source_Budget_Delta'!F18 | G16: =F16-E16 | H16: =IFERROR(G16/E16,0)
A17: ='07_Source_Budget_Delta'!A19 | B17: ='07_Source_Budget_Delta'!B19 | C17: ='07_Source_Budget_Delta'!C19 | D17: ='07_Source_Budget_Delta'!D19 | E17: ='07_Source_Budget_Delta'!E19 | F17: ='07_Source_Budget_Delta'!F19 | G17: =F17-E17 | H17: =IFERROR(G17/E17,0)
A18: ='07_Source_Budget_Delta'!A20 | B18: ='07_Source_Budget_Delta'!B20 | C18: ='07_Source_Budget_Delta'!C20 | D18: ='07_Source_Budget_Delta'!D20 | E18: ='07_Source_Budget_Delta'!E20 | F18: ='07_Source_Budget_Delta'!F20 | G18: =F18-E18 | H18: =IFERROR(G18/E18,0)
A19: ='07_Source_Budget_Delta'!A21 | B19: ='07_Source_Budget_Delta'!B21 | C19: ='07_Source_Budget_Delta'!C21 | D19: ='07_Source_Budget_Delta'!D21 | E19: ='07_Source_Budget_Delta'!E21 | F19: ='07_Source_Budget_Delta'!F21 | G19: =F19-E19 | H19: =IFERROR(G19/E19,0)
A20: ='07_Source_Budget_Delta'!A22 | B20: ='07_Source_Budget_Delta'!B22 | C20: ='07_Source_Budget_Delta'!C22 | D20: ='07_Source_Budget_Delta'!D22 | E20: ='07_Source_Budget_Delta'!E22 | F20: ='07_Source_Budget_Delta'!F22 | G20: =F20-E20 | H20: =IFERROR(G20/E20,0)
A21: ='07_Source_Budget_Delta'!A23 | B21: ='07_Source_Budget_Delta'!B23 | C21: ='07_Source_Budget_Delta'!C23 | D21: ='07_Source_Budget_Delta'!D23 | E21: ='07_Source_Budget_Delta'!E23 | F21: ='07_Source_Budget_Delta'!F23 | G21: =F21-E21 | H21: =IFERROR(G21/E21,0)
... A35: ='07_Source_Budget_Delta'!A37 | B35: ='07_Source_Budget_Delta'!B37 | C35: ='07_Source_Budget_Delta'!C37 | D35: ='07_Source_Budget_Delta'!D37 | E35: ='07_Source_Budget_Delta'!E37 | F35: ='07_Source_Budget_Delta'!F37 | G35: =F35-E35 | H35: =IFERROR(G35/E35,0)

Sheet 02_PORR_Production
A1: Month | B1: PORR declared production / Budget monthly | C1: Cumulative
A2: ='08_Source_PORR_Production'!A7 | B2: ='08_Source_PORR_Production'!B7 | C2: =SUM($B$2:B2)
A3: ='08_Source_PORR_Production'!A8 | B3: ='08_Source_PORR_Production'!B8 | C3: =SUM($B$2:B3)
A4: ='08_Source_PORR_Production'!A9 | B4: ='08_Source_PORR_Production'!B9 | C4: =SUM($B$2:B4)
A5: ='08_Source_PORR_Production'!A10 | B5: ='08_Source_PORR_Production'!B10 | C5: =SUM($B$2:B5)
A6: ='08_Source_PORR_Production'!A11 | B6: ='08_Source_PORR_Production'!B11 | C6: =SUM($B$2:B6)
A7: ='08_Source_PORR_Production'!A12 | B7: ='08_Source_PORR_Production'!B12 | C7: =SUM($B$2:B7)
A8: ='08_Source_PORR_Production'!A13 | B8: ='08_Source_PORR_Production'!B13 | C8: =SUM($B$2:B8)
A9: ='08_Source_PORR_Production'!A14 | B9: ='08_Source_PORR_Production'!B14 | C9: =SUM($B$2:B9)
A10: ='08_Source_PORR_Production'!A15 | B10: ='08_Source_PORR_Production'!B15 | C10: =SUM($B$2:B10)
A11: ='08_Source_PORR_Production'!A16 | B11: ='08_Source_PORR_Production'!B16 | C11: =SUM($B$2:B11)
A12: ='08_Source_PORR_Production'!A17 | B12: ='08_Source_PORR_Production'!B17 | C12: =SUM($B$2:B12)
A13: ='08_Source_PORR_Production'!A18 | B13: ='08_Source_PORR_Production'!B18 | C13: =SUM($B$2:B13)
... A38: ='08_Source_PORR_Production'!A43 | B38: ='08_Source_PORR_Production'!B43 | C38: =SUM($B$2:B38)
A41: Year | B41: Annual total declared
A42: 2025 | B42: =SUMIFS($B$2:$B$38,$A$2:$A$38,"*2025*")
A43: 2026 | B43: =SUMIFS($B$2:$B$38,$A$2:$A$38,"*2026*")
A44: 2027 | B44: =SUMIFS($B$2:$B$38,$A$2:$A$38,"*2027*")
A45: 2028 | B45: =SUMIFS($B$2:$B$38,$A$2:$A$38,"*2028*")

Sheet 03_Milestones
A1: Nota logica
A2: Le milestone qui riportate sono considerate “penalizzate” perché sono classificate nella sezione “Milestones penalizzate” del file Programma Wloclawek_Milestones.xlsx. Non è un calcolo automatico della penale scattata: indica milestone contrattualmente soggette a penale / penalizzabili.
A6: No. | B6: Milestone | C6: Start date | D6: Finish date
A7: 1 | B7: Water pressure test | C7: 46676 | D7: 46676
A8: 2 | B8: Placement of the turbo-generator on the foundation | C8: 46646 | D8: 46646
A9: 3 | B9: Measurement of guaranteed parameters A | C9: 46927 | D9: 46927
A10: 4 | B10: Handover of the ITPO project to operation | C10: 46934 | D10: 46934

Sheet 04_Orders_3M
A1: Type | B1: WBS | C1: Package | D1: Status | E1: Date | F1: Value | G1: Buyer
A2: ='10_Source_Orders_3M'!A2 | B2: ='10_Source_Orders_3M'!B2 | C2: ='10_Source_Orders_3M'!C2 | D2: ='10_Source_Orders_3M'!D2 | E2: ='10_Source_Orders_3M'!E2 | F2: ='10_Source_Orders_3M'!F2 | G2: ='10_Source_Orders_3M'!G2
A3: ='10_Source_Orders_3M'!A3 | B3: ='10_Source_Orders_3M'!B3 | C3: ='10_Source_Orders_3M'!C3 | D3: ='10_Source_Orders_3M'!D3 | E3: ='10_Source_Orders_3M'!E3 | F3: ='10_Source_Orders_3M'!F3 | G3: ='10_Source_Orders_3M'!G3
A4: ='10_Source_Orders_3M'!A4 | B4: ='10_Source_Orders_3M'!B4 | C4: ='10_Source_Orders_3M'!C4 | D4: ='10_Source_Orders_3M'!D4 | E4: ='10_Source_Orders_3M'!E4 | F4: ='10_Source_Orders_3M'!F4 | G4: ='10_Source_Orders_3M'!G4
A5: ='10_Source_Orders_3M'!A5 | B5: ='10_Source_Orders_3M'!B5 | C5: ='10_Source_Orders_3M'!C5 | D5: ='10_Source_Orders_3M'!D5 | E5: ='10_Source_Orders_3M'!E5 | F5: ='10_Source_Orders_3M'!F5 | G5: ='10_Source_Orders_3M'!G5
A6: ='10_Source_Orders_3M'!A6 | B6: ='10_Source_Orders_3M'!B6 | C6: ='10_Source_Orders_3M'!C6 | D6: ='10_Source_Orders_3M'!D6 | E6: ='10_Source_Orders_3M'!E6 | F6: ='10_Source_Orders_3M'!F6 | G6: ='10_Source_Orders_3M'!G6
A7: ='10_Source_Orders_3M'!A7 | B7: ='10_Source_Orders_3M'!B7 | C7: ='10_Source_Orders_3M'!C7 | D7: ='10_Source_Orders_3M'!D7 | E7: ='10_Source_Orders_3M'!E7 | F7: ='10_Source_Orders_3M'!F7 | G7: ='10_Source_Orders_3M'!G7
A8: ='10_Source_Orders_3M'!A8 | B8: ='10_Source_Orders_3M'!B8 | C8: ='10_Source_Orders_3M'!C8 | D8: ='10_Source_Orders_3M'!D8 | E8: ='10_Source_Orders_3M'!E8 | F8: ='10_Source_Orders_3M'!F8 | G8: ='10_Source_Orders_3M'!G8
A9: ='10_Source_Orders_3M'!A9 | B9: ='10_Source_Orders_3M'!B9 | C9: ='10_Source_Orders_3M'!C9 | D9: ='10_Source_Orders_3M'!D9 | E9: ='10_Source_Orders_3M'!E9 | F9: ='10_Source_Orders_3M'!F9 | G9: ='10_Source_Orders_3M'!G9
A10: ='10_Source_Orders_3M'!A10 | B10: ='10_Source_Orders_3M'!B10 | C10: ='10_Source_Orders_3M'!C10 | D10: ='10_Source_Orders_3M'!D10 | E10: ='10_Source_Orders_3M'!E10 | F10: ='10_Source_Orders_3M'!F10 | G10: ='10_Source_Orders_3M'!G10
A11: ='10_Source_Orders_3M'!A11 | B11: ='10_Source_Orders_3M'!B11 | C11: ='10_Source_Orders_3M'!C11 | D11: ='10_Source_Orders_3M'!D11 | E11: ='10_Source_Orders_3M'!E11 | F11: ='10_Source_Orders_3M'!F11 | G11: ='10_Source_Orders_3M'!G11
A12: ='10_Source_Orders_3M'!A12 | B12: ='10_Source_Orders_3M'!B12 | C12: ='10_Source_Orders_3M'!C12 | D12: ='10_Source_Orders_3M'!D12 | E12: ='10_Source_Orders_3M'!E12 | F12: ='10_Source_Orders_3M'!F12 | G12: ='10_Source_Orders_3M'!G12
A13: ='10_Source_Orders_3M'!A13 | B13: ='10_Source_Orders_3M'!B13 | C13: ='10_Source_Orders_3M'!C13 | D13: ='10_Source_Orders_3M'!D13 | E13: ='10_Source_Orders_3M'!E13 | F13: ='10_Source_Orders_3M'!F13 | G13: ='10_Source_Orders_3M'!G13
... A121: ='10_Source_Orders_3M'!A121 | B121: ='10_Source_Orders_3M'!B121 | C121: ='10_Source_Orders_3M'!C121 | D121: ='10_Source_Orders_3M'!D121 | E121: ='10_Source_Orders_3M'!E121 | F121: ='10_Source_Orders_3M'!F121 | G121: ='10_Source_Orders_3M'!G121

Sheet 05_Status_Mix
A1: Status group | B1: Count | C1: Value | D1: % Value | E1: % Count
A2: ='09_Source_Status_Mix'!A9 | B2: ='09_Source_Status_Mix'!B9 | C2: ='09_Source_Status_Mix'!C9 | D2: ='09_Source_Status_Mix'!D9 | E2: ='09_Source_Status_Mix'!E9
A3: ='09_Source_Status_Mix'!A10 | B3: ='09_Source_Status_Mix'!B10 | C3: ='09_Source_Status_Mix'!C10 | D3: ='09_Source_Status_Mix'!D10 | E3: ='09_Source_Status_Mix'!E10
A4: ='09_Source_Status_Mix'!A11 | B4: ='09_Source_Status_Mix'!B11 | C4: ='09_Source_Status_Mix'!C11 | D4: ='09_Source_Status_Mix'!D11 | E4: ='09_Source_Status_Mix'!E11
A6: Nota: perimetro limitato ai soli ordini diretti (root group 1-7); esclusi indiretti/servizi e opportunities/risks.

Sheet 06_S_Curve_Data
A1: Month | B1: Label | C1: Procurement monthly | D1: Procurement cumulative | E1: Budget monthly | F1: Budget cumulative | G1: Contracted monthly | H1: Contracted cumulative | I1: Current marker
A2: ='11_Source_S_Curve_Data'!A10 | B2: ='11_Source_S_Curve_Data'!B10 | C2: ='11_Source_S_Curve_Data'!C10 | D2: ='11_Source_S_Curve_Data'!D10 | E2: ='11_Source_S_Curve_Data'!E10 | F2: ='11_Source_S_Curve_Data'!F10 | G2: ='11_Source_S_Curve_Data'!G10 | H2: ='11_Source_S_Curve_Data'!H10 | I2: ='11_Source_S_Curve_Data'!I10
A3: ='11_Source_S_Curve_Data'!A11 | B3: ='11_Source_S_Curve_Data'!B11 | C3: ='11_Source_S_Curve_Data'!C11 | D3: ='11_Source_S_Curve_Data'!D11 | E3: ='11_Source_S_Curve_Data'!E11 | F3: ='11_Source_S_Curve_Data'!F11 | G3: ='11_Source_S_Curve_Data'!G11 | H3: ='11_Source_S_Curve_Data'!H11 | I3: ='11_Source_S_Curve_Data'!I11
A4: ='11_Source_S_Curve_Data'!A12 | B4: ='11_Source_S_Curve_Data'!B12 | C4: ='11_Source_S_Curve_Data'!C12 | D4: ='11_Source_S_Curve_Data'!D12 | E4: ='11_Source_S_Curve_Data'!E12 | F4: ='11_Source_S_Curve_Data'!F12 | G4: ='11_Source_S_Curve_Data'!G12 | H4: ='11_Source_S_Curve_Data'!H12 | I4: ='11_Source_S_Curve_Data'!I12
A5: ='11_Source_S_Curve_Data'!A13 | B5: ='11_Source_S_Curve_Data'!B13 | C5: ='11_Source_S_Curve_Data'!C13 | D5: ='11_Source_S_Curve_Data'!D13 | E5: ='11_Source_S_Curve_Data'!E13 | F5: ='11_Source_S_Curve_Data'!F13 | G5: ='11_Source_S_Curve_Data'!G13 | H5: ='11_Source_S_Curve_Data'!H13 | I5: ='11_Source_S_Curve_Data'!I13
A6: ='11_Source_S_Curve_Data'!A14 | B6: ='11_Source_S_Curve_Data'!B14 | C6: ='11_Source_S_Curve_Data'!C14 | D6: ='11_Source_S_Curve_Data'!D14 | E6: ='11_Source_S_Curve_Data'!E14 | F6: ='11_Source_S_Curve_Data'!F14 | G6: ='11_Source_S_Curve_Data'!G14 | H6: ='11_Source_S_Curve_Data'!H14 | I6: ='11_Source_S_Curve_Data'!I14
A7: ='11_Source_S_Curve_Data'!A15 | B7: ='11_Source_S_Curve_Data'!B15 | C7: ='11_Source_S_Curve_Data'!C15 | D7: ='11_Source_S_Curve_Data'!D15 | E7: ='11_Source_S_Curve_Data'!E15 | F7: ='11_Source_S_Curve_Data'!F15 | G7: ='11_Source_S_Curve_Data'!G15 | H7: ='11_Source_S_Curve_Data'!H15 | I7: ='11_Source_S_Curve_Data'!I15
A8: ='11_Source_S_Curve_Data'!A16 | B8: ='11_Source_S_Curve_Data'!B16 | C8: ='11_Source_S_Curve_Data'!C16 | D8: ='11_Source_S_Curve_Data'!D16 | E8: ='11_Source_S_Curve_Data'!E16 | F8: ='11_Source_S_Curve_Data'!F16 | G8: ='11_Source_S_Curve_Data'!G16 | H8: ='11_Source_S_Curve_Data'!H16 | I8: ='11_Source_S_Curve_Data'!I16
A9: ='11_Source_S_Curve_Data'!A17 | B9: ='11_Source_S_Curve_Data'!B17 | C9: ='11_Source_S_Curve_Data'!C17 | D9: ='11_Source_S_Curve_Data'!D17 | E9: ='11_Source_S_Curve_Data'!E17 | F9: ='11_Source_S_Curve_Data'!F17 | G9: ='11_Source_S_Curve_Data'!G17 | H9: ='11_Source_S_Curve_Data'!H17 | I9: ='11_Source_S_Curve_Data'!I17
A10: ='11_Source_S_Curve_Data'!A18 | B10: ='11_Source_S_Curve_Data'!B18 | C10: ='11_Source_S_Curve_Data'!C18 | D10: ='11_Source_S_Curve_Data'!D18 | E10: ='11_Source_S_Curve_Data'!E18 | F10: ='11_Source_S_Curve_Data'!F18 | G10: ='11_Source_S_Curve_Data'!G18 | H10: ='11_Source_S_Curve_Data'!H18 | I10: ='11_Source_S_Curve_Data'!I18
A11: ='11_Source_S_Curve_Data'!A19 | B11: ='11_Source_S_Curve_Data'!B19 | C11: ='11_Source_S_Curve_Data'!C19 | D11: ='11_Source_S_Curve_Data'!D19 | E11: ='11_Source_S_Curve_Data'!E19 | F11: ='11_Source_S_Curve_Data'!F19 | G11: ='11_Source_S_Curve_Data'!G19 | H11: ='11_Source_S_Curve_Data'!H19 | I11: ='11_Source_S_Curve_Data'!I19
A12: ='11_Source_S_Curve_Data'!A20 | B12: ='11_Source_S_Curve_Data'!B20 | C12: ='11_Source_S_Curve_Data'!C20 | D12: ='11_Source_S_Curve_Data'!D20 | E12: ='11_Source_S_Curve_Data'!E20 | F12: ='11_Source_S_Curve_Data'!F20 | G12: ='11_Source_S_Curve_Data'!G20 | H12: ='11_Source_S_Curve_Data'!H20 | I12: ='11_Source_S_Curve_Data'!I20
A13: ='11_Source_S_Curve_Data'!A21 | B13: ='11_Source_S_Curve_Data'!B21 | C13: ='11_Source_S_Curve_Data'!C21 | D13: ='11_Source_S_Curve_Data'!D21 | E13: ='11_Source_S_Curve_Data'!E21 | F13: ='11_Source_S_Curve_Data'!F21 | G13: ='11_Source_S_Curve_Data'!G21 | H13: ='11_Source_S_Curve_Data'!H21 | I13: ='11_Source_S_Curve_Data'!I21
... A38: ='11_Source_S_Curve_Data'!A46 | B38: ='11_Source_S_Curve_Data'!B46 | C38: ='11_Source_S_Curve_Data'!C46 | D38: ='11_Source_S_Curve_Data'!D46 | E38: ='11_Source_S_Curve_Data'!E46 | F38: ='11_Source_S_Curve_Data'!F46 | G38: ='11_Source_S_Curve_Data'!G46 | H38: ='11_Source_S_Curve_Data'!H46 | I38: ='11_Source_S_Curve_Data'!I46

Sheet 07_Source_Budget_Delta
A1: Nota origine dati
A2: Dati estratti dal file Budget in data/current: Budget.xlsm, sheet Włocławek Budget. Totale Budget 0 = cella I12; Budget attuale = cella AB12. La tabella WBS sotto riporta le righe top-level trovate in colonna A: WBS 1-8 della sezione costi diretti e WBS 1-17 della sezione riepilogo/finanziaria. I valori Budget 0 e Budget attuale derivano rispettivamente dalle colonne I e AB; Delta e Delta % sono formule nel report.
A6: Metric | B6: Value | C6: Source file | D6: Source sheet | E6: Source cell
A7: Budget 0 - col. I | B7: 505343424 | C7: Budget.xlsm | D7: Włocławek Budget | E7: I12
A8: Budget attuale - col. AB | B8: 5.0145785e+08 | C8: Budget.xlsm | D8: Włocławek Budget | E8: AB12
A11: Section | B11: WBS | C11: Description PL | D11: Description EN | E11: Budget 0 - col. I | F11: Budget attuale - col. AB | G11: Delta AB-I | H11: Delta % | I11: Source row | J11: Source cells
A12: Direct cost / root budget group | B12: 1 | C12: PROJEKTOWANIE | D12: DESIGN | E12: 30550000 | F12: 27170000 | G12: =F12-E12 | H12: =IFERROR(G12/E12,0) | I12: 13 | J12: I13 / AB13
A13: Direct cost / root budget group | B13: 2 | C13: Roboty branży budowlano-konstrukcyjnej | D13: Civil works | E13: 113409768 | F13: 1.0810977e+08 | G13: =F13-E13 | H13: =IFERROR(G13/E13,0) | I13: 38 | J13: I38 / AB38
A14: Direct cost / root budget group | B14: 3 | C14: BRANŻA ELEKTRYCZNA | D14: ELECTRICAL WORKS | E14: 10912000 | F14: 58345340 | G14: =F14-E14 | H14: =IFERROR(G14/E14,0) | I14: 149 | J14: I149 / AB149
A15: Direct cost / root budget group | B15: 4 | C15: Roboty branży sanitarnej i ppoż | D15: Sanitary works and fire-fighting system | E15: 34223555 | F15: 21293319 | G15: =F15-E15 | H15: =IFERROR(G15/E15,0) | I15: 166 | J15: I166 / AB166
A16: Direct cost / root budget group | B16: 5 | C16: Roboty branży mechanicznej i technologicznej | D16: Mechanical and technological works | E16: 293798902 | F16: 2.5866665e+08 | G16: =F16-E16 | H16: =IFERROR(G16/E16,0) | I16: 191 | J16: I191 / AB191
A17: Direct cost / root budget group | B17: 6 | C17: Zimny i gorący rozruch, Ruch próbny instalacji technologicznych | D17: Cold and hot commissioning & Trial run of technological equipment | E17: 8499199 | F17: 8500000 | G17: =F17-E17 | H17: =IFERROR(G17/E17,0) | I17: 265 | J17: I265 / AB265
A18: Financial summary / WBS 1-17 | B18: 7 | C18: Wyrównanie do wartości z TCO / Rezerwa | D18: Alignment to TCO values / Backup | E18: 0 | F18: 538352 | G18: =F18-E18 | H18: =IFERROR(G18/E18,0) | I18: 284 | J18: I284 / AB284
A19: Financial summary / WBS 1-17 | B19: 8 | C19: Pozostałe koszty | E19: 0 | F19: 414429 | G19: =F19-E19 | H19: =IFERROR(G19/E19,0) | I19: 287 | J19: I287 / AB287
A20: Financial summary / WBS 1-17 | B20: 1 | C20: TKW | E20: 505757853 | F20: 5.0145785e+08 | G20: =F20-E20 | H20: =IFERROR(G20/E20,0) | I20: 291 | J20: I291 / AB291
A21: Financial summary / WBS 1-17 | B21: 1 | C21: PERSONEL | D21: STAFF | E21: 0 | F21: 0 | G21: =F21-E21 | H21: =IFERROR(G21/E21,0) | I21: 298 | J21: I298 / AB298
A22: Financial summary / WBS 1-17 | B22: 2 | C22: TKW Razem | D22: Direct + indirect costs | E22: 5.4614887e+08 | F22: 5.6359321e+08 | G22: =F22-E22 | H22: =IFERROR(G22/E22,0) | I22: 440 | J22: I440 / AB440
A23: Financial summary / WBS 1-17 | B23: 3 | C23: Kwota narzutów kalkulacyjnych | E23: 85237133 | F23: 63492795 | G23: =F23-E23 | H23: =IFERROR(G23/E23,0) | I23: 441 | J23: I441 / AB441
A24: Financial summary / WBS 1-17 | B24: 4 | C24: % narzutów kalkulacyjnych | E24: 0.15606941 | F24: 0.11265713 | G24: =F24-E24 | H24: =IFERROR(G24/E24,0) | I24: 442 | J24: I442 / AB442
A25: Financial summary / WBS 1-17 | B25: 5 | C25: Zlecenie otrzymane/Planowany przerób | E25: 631386000 | F25: 627086000 | G25: =F25-E25 | H25: =IFERROR(G25/E25,0) | I25: 452 | J25: I452 / AB452
A26: Financial summary / WBS 1-17 | B26: 6 | C26: Podwykonawstwo wewn. udzielone | E26: 0 | F26: 0 | G26: =F26-E26 | H26: =IFERROR(G26/E26,0) | I26: 453 | J26: I453 / AB453
A27: Financial summary / WBS 1-17 | B27: 7 | C27: Planowany Przerób po REGIE | D27: Planned capacity (REGIE) | E27: 631386000 | F27: 627086000 | G27: =F27-E27 | H27: =IFERROR(G27/E27,0) | I27: 454 | J27: I454 / AB454
A28: Financial summary / WBS 1-17 | B28: 8 | C28: Korekta kosztowa wpływająca tylko na wynik | E28: 0 | F28: 0 | G28: =F28-E28 | H28: =IFERROR(G28/E28,0) | I28: 457 | J28: I457 / AB457
A29: Financial summary / WBS 1-17 | B29: 9 | C29: Kwota narzutów kalkulacyjnych | E29: 85237133 | F29: 63492795 | G29: =F29-E29 | H29: =IFERROR(G29/E29,0) | I29: 458 | J29: I458 / AB458
A30: Financial summary / WBS 1-17 | B30: 10 | C30: Kwota narzutów kalkulacyjnych po korekcie | D30: Amount of imputed mark-ups after correction | E30: 0 | F30: 63492795 | G30: =F30-E30 | H30: =IFERROR(G30/E30,0) | I30: 459 | J30: I459 / AB459
A31: Financial summary / WBS 1-17 | B31: 11 | C31: Alokacje - REGIE | E31: 45080960 | F31: 31178095 | G31: =F31-E31 | H31: =IFERROR(G31/E31,0) | I31: 475 | J31: I475 / AB475
A32: Financial summary / WBS 1-17 | B32: 12 | C32: EBT w PLN - po uwzględnieniu REGIE | E32: 40156172 | F32: 32314699 | G32: =F32-E32 | H32: =IFERROR(G32/E32,0) | I32: 477 | J32: I477 / AB477
A33: Financial summary / WBS 1-17 | B33: 13 | C33: % EBT bez revaluation | E33: 0.063600036 | F33: 0.051531527 | G33: =F33-E33 | H33: =IFERROR(G33/E33,0) | I33: 478 | J33: I478 / AB478
A34: Financial summary / WBS 1-17 | B34: 14 | C34: EBT z Rewaluation | E34: 40156172 | F34: 54413234 | G34: =F34-E34 | H34: =IFERROR(G34/E34,0) | I34: 480 | J34: I480 / AB480
A35: Financial summary / WBS 1-17 | B35: 15 | C35: % EBT bez Contingency | E35: 0.063600036 | F35: 0.086771566 | G35: =F35-E35 | H35: =IFERROR(G35/E35,0) | I35: 481 | J35: I481 / AB481
A36: Financial summary / WBS 1-17 | B36: 16 | C36: Wartość robót wykonywanych przez konsorcjantów | E36: 0 | F36: 0 | G36: =F36-E36 | H36: =IFERROR(G36/E36,0) | I36: 488 | J36: I488 / AB488
A37: Financial summary / WBS 1-17 | B37: 17 | C37: Łączna wartość kontraktu (BBB + konsorcjanci) | E37: 631386000 | F37: 627086000 | G37: =F37-E37 | H37: =IFERROR(G37/E37,0) | I37: 489 | J37: I489 / AB489

Sheet 08_Source_PORR_Production
A1: Nota origine dati
A2: Dati estratti dal file Budget in data/current: Budget.xlsm, sheet Włocławek Budget. La produzione mensile dichiarata PORR / budget monthly deriva dalla riga 12, colonne AM:BW; le intestazioni mese sono sulla riga 11.
A6: Month | B6: Value | C6: Source cell | D6: Source header cell
A7: 2025-12-01 00:00:00 | B7: 6199140 | C7: AM12 | D7: AM11
A8: 2026-01-01 00:00:00 | B8: 1209845 | C8: AN12 | D8: AN11
A9: 2026-02-01 00:00:00 | B9: 4914057.8 | C9: AO12 | D9: AO11
A10: 2026-03-01 00:00:00 | B10: 6224860.5 | C10: AP12 | D10: AP11
A11: 2026-04-01 00:00:00 | B11: 3080461.3 | C11: AQ12 | D11: AQ11
A12: 2026-05-01 00:00:00 | B12: 10298268 | C12: AR12 | D12: AR11
A13: 2026-06-01 00:00:00 | B13: 24920618 | C13: AS12 | D13: AS11
A14: 2026-07-01 00:00:00 | B14: 11044596 | C14: AT12 | D14: AT11
A15: 2026-08-01 00:00:00 | B15: 12651060 | C15: AU12 | D15: AU11
A16: 2026-09-01 00:00:00 | B16: 16840968 | C16: AV12 | D16: AV11
A17: 2026-10-01 00:00:00 | B17: 21259071 | C17: AW12 | D17: AW11
A18: 2026-11-01 00:00:00 | B18: 17153972 | C18: AX12 | D18: AX11
... A43: 2028-12-01 00:00:00 | B43: 44750308 | C43: BW12 | D43: BW11

Sheet 09_Source_Status_Mix
A1: Nota origine e logica calcolo
A2: Dati derivati dal file Procurement in data/current, sheet Procurement Schedule. PERIMETRO: solo ordini diretti, root group 1-7; sono esclusi 8 = indiretti/servizi e 9 = opportunities/risks. Colonne di riferimento: Q = stato procurement, S = Budget AK / budget aggiornato, T = valore contracted quando disponibile. Raggruppamento: Closed / Finalized / PCT approval = Ordinato; Planned = Da ordinare; tutti gli altri stati attivi = In negoziazione. Count = numero pacchetti nel gruppo; Value = somma economica del gruppo; % Value = Value gruppo / totale Value; % Count = Count gruppo / totale Count.
A8: Status group | B8: Count | C8: Value | D8: % Value | E8: % Count
A9: Ordinato | B9: 42 | C9: 2.6649155e+08 | D9: =IFERROR(C9/SUM($C$9:$C$11),0) | E9: =IFERROR(B9/SUM($B$9:$B$11),0)
A10: In negoziazione | B10: 45 | C10: 1.0517755e+08 | D10: =IFERROR(C10/SUM($C$9:$C$11),0) | E10: =IFERROR(B10/SUM($B$9:$B$11),0)
A11: Da ordinare | B11: 124 | C11: 133674322 | D11: =IFERROR(C11/SUM($C$9:$C$11),0) | E11: =IFERROR(B11/SUM($B$9:$B$11),0)

Sheet 10_Source_Orders_3M
A1: Type | B1: WBS | C1: Package | D1: Status | E1: Date | F1: Value | G1: Buyer
A2: Closed last 3 months | B2: 8.5.1 | C2: Internet Connection ECd_37 | D2: closed | E2: 46073 | F2: 27350
A3: Closed last 3 months | B3: 8.1.3.3 | C3: Open order - sanitary industry assortment ECd_39 | D3: closed | E3: 46077 | F3: 30000
A4: Closed last 3 months | B4: 8.1.3.4 | C4: Open order - sanitary industry assortment ECd_40 | D4: closed | E4: 46077 | F4: 30000
A5: Closed last 3 months | B5: 1.2.2 | C5: Detailed design: boiler support steel structure and equipment support structures | D5: closed | E5: 46080 | F5: 943000
A6: Closed last 3 months | B6: 8.4.1.1 | C6: Personal Occupational Health and Safety Equipment ECd_43 | D6: closed | E6: 46090 | F6: 30000
A7: Closed last 3 months | B7: 8.3.1.2 | C7: Generator rental ECd_44 | D7: closed | E7: 46096 | F7: 23904
A8: Closed last 3 months | B8: 8.7.1.6 | C8: Purchase of road signs ECd_42 | D8: closed | E8: 46096 | F8: 2000
A9: Closed last 3 months | B9: 8.7.1.7 | C9: Purchase of rubble for the construction of storage yards and work platforms ECd_45 | D9: closed | E9: 46096 | F9: 83200
A10: Closed last 3 months | B10: 2.11.5.3 | C10: Concrete slab installation on the ground | D10: closed | E10: 46106 | F10: 1735392.8 | G10: Agnieszka Zając
A11: Closed last 3 months | B11: 2.14.2.2 | C11: External road - aggregate delivery ECd_46 | D11: closed | E11: 46106 | F11: 134400 | G11: Agnieszka Zając
A12: Closed last 3 months | B12: 2.4.1 | C12: Insulation - work | D12: closed | E12: 46106 | F12: 733045.25 | G12: Agnieszka Zając
A13: Closed last 3 months | B13: 2.5.1.3 | C13: Construction of reinforced concrete foundations and underground structures | D13: closed | E13: 46106 | F13: 5276959.4 | G13: Agnieszka Zając
A14: Closed last 3 months | B14: 2.5.2.1 | C14: Reinforced concrete structure of the above-ground part of the B1 building - delivery and assembly of prefabricated elements | D14: closed | E14: 46106 | F14: 16616880 | G14: Jan Szczubiał
A15: Closed last 3 months | B15: 2.5.2.2.3 | C15: Reinforced concrete structure of the above-ground part of the B3 building - delivery and assembly of prefabricated elements | D15: closed | E15: 46106 | F15: 2115950 | G15: Jan Szczubiał
A16: Closed last 3 months | B16: 2.5.2.2.4 | C16: Reinforced concrete structure of the above-ground part of the other buildings | D16: closed | E16: 46106 | F16: 708072.75 | G16: Jan Szczubiał
A17: Closed last 3 months | B17: 2.6.2.1 | C17: Precast reinforced concrete structure of facility B3 (change from steel structure compared to the acquisition stage) | D17: closed | E17: 46106 | F17: 1004390 | G17: Robert Klimczak
A18: Closed last 3 months | B18: 2.6.3.1 | C18: Precast reinforced concrete structure of facility B4 (change from steel structure compared to the acquisition stage) | D18: closed | E18: 46106 | F18: 246780 | G18: Robert Klimczak
A19: Closed last 3 months | B19: 2.14.2.1 | C19: External road- sub-base construction | D19: closed | E19: 46122 | F19: 250640 | G19: Agnieszka Zając
A20: Closed last 3 months | B20: 8.3.1.1 | C20: Electricity Costs | D20: closed | E20: 46122 | F20: 100000
A21: Closed last 3 months | B21: 8.7.1.4 | C21: Construction of aggregate squares | D21: closed | E21: 46122 | F21: 124700 | G21: Agnieszka Zając
A22: Closed last 3 months | B22: 8.8.4 | C22: Removing collisions related to site preparation and construction | D22: closed | E22: 46122 | F22: 0
A23: Closed last 3 months | B23: 8.8.4.1 | C23: Removal of existing reinforced concrete foundations in the vicinity of Building B2 | D23: closed | E23: 46122 | F23: 50000
A24: Closed last 3 months | B24: 5.10.2 | C24: Auxiliary crane and hoists for the maintenance of the steam turbine | D24: closed | E24: 46125 | F24: 499000 | G24: Magdalena Białorucka
A25: Closed last 3 months | B25: 5.2.1 | C25: Overhead crane, grab and operator seat + Spare Grab | D25: closed | E25: 46125 | F25: 8701000 | G25: Magdalena Białorucka
A26: Closed last 3 months | B26: 5.11 | C26: Stack | D26: closed | E26: 46127 | F26: 1498200 | G26: Magdalena Białorucka
A27: Closed last 3 months | B27: 5.4.1.1 | C27: Boiler - pressure parts | D27: closed | E27: 46127 | F27: 45990000 | G27: Roger Gołombek
A28: Closed last 3 months | B28: 8.3.5 | C28: Construction Waste Removal ECd_38 | D28: closed | E28: 46127 | F28: 290720
A29: Closed last 3 months | B29: 2.3 | C29: Drainage | D29: closed | E29: 46129 | F29: 0
A30: Closed last 3 months | B30: 2.3.1 | C30: Rental of an drainage pump ECd_49 | D30: closed | E30: 46129 | F30: 4600
A31: Closed last 3 months | B31: 2.3.2 | C31: Mobilization, installation and leasing of a wellpoint system including pumps ECd_50 | D31: closed | E31: 46129 | F31: 70000
A32: Closed last 3 months | B32: 1.2.4 | C32: Electrical & I/C detailed design | D32: closed | E32: 46134 | F32: 1620000
A33: Closed last 3 months | B33: 3.1.1 | C33: Delivery and installation of electrical equipment | D33: closed | E33: 46134 | F33: 0 | G33: Radosław Zdancewicz
A34: Closed last 3 months | B34: 3.1.1.1 | C34: Delivery and installation of electrical equipment | D34: closed | E34: 46134 | F34: 27750000 | G34: Radosław Zdancewicz
A35: Closed last 3 months | B35: 3.2 | C35: Teletechnical installations | D35: closed | E35: 46134 | F35: 1750000 | G35: Radosław Zdancewicz
A36: Closed last 3 months | B36: 3.4.1 | C36: Automation system and instrumentation, communication networks and control room devices | D36: closed | E36: 46134 | F36: 0 | G36: Radosław Zdancewicz
A37: Closed last 3 months | B37: 3.4.1.1 | C37: Automation system and instrumentation, communication networks and control room devices | D37: closed | E37: 46134 | F37: 6280000 | G37: Radosław Zdancewicz
A38: Closed last 3 months | B38: 6.4.1 | C38: Extension of the guarantee and warranty period to 48 months for electrical, technical and I&C works | D38: closed | E38: 46134 | F38: 350000 | G38: Radosław Zdancewicz
A39: Closed last 3 months | B39: 5.10.1 | C39: Steam turbine - gear box - generator. Including accessories: oil system, coolers, insulation, pipes and valves, control panel, protection panel, synchro system etc. | D39: PCT/approval | E39: 46137 | F39: 0 | G39: Magdalena Białorucka / Stanisław Rucki
A40: Closed last 3 months | B40: 5.8.1 | C40: Chain conveyor under grate + Bottom ash extractor + Vibrating table / bulk screen | D40: PCT/approval | E40: 46137 | F40: 1462000 | G40: Stanisław Rucki
...

Sheet 11_Source_S_Curve_Data
A1: Nota origine e logica calcolo
A2: La Curva S deriva dal dashboard payload rigenerato dai file Excel in data/current. Procurement schedule cumulativo: somma mensile/cumulata dei valori Updated Budget / Budget AK del Procurement Schedule secondo le date procurement. Budget Baseline cumulativo: curva mensile/cumulata letta dal Budget, riga 12, colonne AM:BW. Ordini contrattualizzati cumulativo: somma mensile/cumulata dei valori Contracted secondo le date di chiusura/contrattualizzazione disponibili nel Procurement Schedule.
A9: Month | B9: Label | C9: Procurement monthly | D9: Procurement cumulative | E9: Budget monthly | F9: Budget cumulative | G9: Contracted monthly | H9: Contracted cumulative | I9: Current marker
A10: 2025-12 | B10: dic-2025 | C10: 115638522 | D10: 115638522 | E10: 6228403.1 | F10: 6228403.1 | G10: 6555456.1 | H10: 6555456.1
A11: 2026-01 | B11: gen-2026 | C11: 4696881.3 | D11: 1.203354e+08 | E11: 998971.02 | F11: 7227374.1 | G11: 9148590.3 | H11: 15704046
A12: 2026-02 | B12: feb-2026 | C12: 13016819 | D12: 1.3335222e+08 | E12: 6546793.1 | F12: 13774167 | G12: 13741424 | H12: 29445471
A13: 2026-03 | B13: mar-2026 | C13: 39428853 | D13: 1.7278108e+08 | E13: 7145462.3 | F13: 20919630 | G13: 14865181 | H13: 44310652
A14: 2026-04 | B14: apr-2026 | C14: 1.3527896e+08 | D14: 3.0806004e+08 | E14: 4544159 | F14: 25463788 | G14: 16222395 | H14: 60533047
A15: 2026-05 | B15: mag-2026 | C15: 16056897 | D15: 3.2411694e+08 | E15: 11387969 | F15: 36851757 | G15: 16790332 | H15: 77323379 | I15: Current
A16: 2026-06 | B16: giu-2026 | C16: 35693098 | D16: 3.5981003e+08 | E16: 26104197 | F16: 62955954 | G16: 21850916 | H16: 99174296
A17: 2026-07 | B17: lug-2026 | C17: 35205785 | D17: 3.9501582e+08 | E17: 12262725 | F17: 75218679 | G17: 21806399 | H17: 1.2098069e+08
A18: 2026-08 | B18: ago-2026 | C18: 37206712 | D18: 4.3222253e+08 | E18: 13885536 | F18: 89104215 | G18: 15455316 | H18: 1.3643601e+08
A19: 2026-09 | B19: set-2026 | C19: 11736183 | D19: 4.4395871e+08 | E19: 18199644 | F19: 1.0730386e+08 | G19: 15455316 | H19: 1.5189133e+08
A20: 2026-10 | B20: ott-2026 | C20: 8322295 | D20: 4.5228101e+08 | E20: 22641476 | F20: 1.2994534e+08 | G20: 15455316 | H20: 1.6734664e+08
A21: 2026-11 | B21: nov-2026 | C21: 1400000 | D21: 4.5368101e+08 | E21: 18485898 | F21: 1.4843123e+08 | G21: 12386679 | H21: 1.7973332e+08
A22: 2026-12 | B22: dic-2026 | C22: 2993740 | D22: 4.5667475e+08 | E22: 21087648 | F22: 1.6951888e+08 | G22: 12199404 | H22: 1.9193273e+08
A23: 2027-01 | B23: gen-2027 | C23: 2200000 | D23: 4.5887475e+08 | E23: 26282567 | F23: 1.9580145e+08 | G23: 10995165 | H23: 2.0292789e+08
A24: 2027-02 | B24: feb-2027 | C24: 32264194 | D24: 4.9113894e+08 | E24: 29588645 | F24: 2.2539009e+08 | G24: 10075165 | H24: 2.1300306e+08
A25: 2027-03 | B25: mar-2027 | C25: 700000 | D25: 4.9183894e+08 | E25: 36812234 | F25: 2.6220233e+08 | G25: 10075165 | H25: 2.2307822e+08
A26: 2027-04 | B26: apr-2027 | C26: 9497187.3 | D26: 5.0133613e+08 | E26: 32191042 | F26: 2.9439337e+08 | G26: 10075165 | H26: 2.3315339e+08
A27: 2027-05 | B27: mag-2027 | C27: 0 | D27: 5.0133613e+08 | E27: 33377225 | F27: 3.277706e+08 | G27: 3908667.5 | H27: 2.3706205e+08
... A46: 2028-12 | B46: dic-2028 | C46: 0 | D46: 5.0612538e+08 | E46: 50310826 | F46: 5.6359321e+08 | G46: 0 | H46: 2.7467847e+08
