Workbook

Sheet TABLE DASHBOARD
B1: ORDINATO | C1: DA ORDINARE
A2: DESIGN | B2: {=IFERROR(INDEX('JV RIEPILOGO'!$M:$M,MATCH($A2,'JV RIEPILOGO'!$B:$B,0)+1),"")} -> 24886974 | C2: =IFERROR(SUM(INDEX('JV RIEPILOGO'!$M:$M,MATCH($A2,'JV RIEPILOGO'!$B:$B,0)+2),INDEX('JV RIEPILOGO'!$M:$M,MATCH($A2,'JV RIEPILOGO'!$B:$B,0)+3)),"") -> 20703026
A3: CIVIL WORKS | B3: {=IFERROR(INDEX('JV RIEPILOGO'!$M:$M,MATCH($A3,'JV RIEPILOGO'!$B:$B,0)+1),"")} -> 53496524 | C3: =IFERROR(SUM(INDEX('JV RIEPILOGO'!$M:$M,MATCH($A3,'JV RIEPILOGO'!$B:$B,0)+2),INDEX('JV RIEPILOGO'!$M:$M,MATCH($A3,'JV RIEPILOGO'!$B:$B,0)+3)),"") -> 54613243
A4: ELECTRICAL WORKS | B4: {=IFERROR(INDEX('JV RIEPILOGO'!$M:$M,MATCH($A4,'JV RIEPILOGO'!$B:$B,0)+1),"")} -> 36070000 | C4: =IFERROR(SUM(INDEX('JV RIEPILOGO'!$M:$M,MATCH($A4,'JV RIEPILOGO'!$B:$B,0)+2),INDEX('JV RIEPILOGO'!$M:$M,MATCH($A4,'JV RIEPILOGO'!$B:$B,0)+3)),"") -> 22275340
A5: SANITARY WORKS AND FF | B5: {=IFERROR(INDEX('JV RIEPILOGO'!$M:$M,MATCH($A5,'JV RIEPILOGO'!$B:$B,0)+1),"")} -> 0 | C5: =IFERROR(SUM(INDEX('JV RIEPILOGO'!$M:$M,MATCH($A5,'JV RIEPILOGO'!$B:$B,0)+2),INDEX('JV RIEPILOGO'!$M:$M,MATCH($A5,'JV RIEPILOGO'!$B:$B,0)+3)),"") -> 21293319
A6: MECHANICAL AND TECHNOLOGICAL | B6: {=IFERROR(INDEX('JV RIEPILOGO'!$M:$M,MATCH($A6,'JV RIEPILOGO'!$B:$B,0)+1),"")} -> 1.5305376e+08 | C6: =IFERROR(SUM(INDEX('JV RIEPILOGO'!$M:$M,MATCH($A6,'JV RIEPILOGO'!$B:$B,0)+2),INDEX('JV RIEPILOGO'!$M:$M,MATCH($A6,'JV RIEPILOGO'!$B:$B,0)+3)),"") -> 1.0561288e+08
A7: COMMISSIONING | B7: {=IFERROR(INDEX('JV RIEPILOGO'!$M:$M,MATCH($A7,'JV RIEPILOGO'!$B:$B,0)+1),"")} -> 100000 | C7: =IFERROR(SUM(INDEX('JV RIEPILOGO'!$M:$M,MATCH($A7,'JV RIEPILOGO'!$B:$B,0)+2),INDEX('JV RIEPILOGO'!$M:$M,MATCH($A7,'JV RIEPILOGO'!$B:$B,0)+3)),"") -> 8400000
A8: ALIGNEMENT AND BACKUP | B8: {=IFERROR(INDEX('JV RIEPILOGO'!$M:$M,MATCH($A8,'JV RIEPILOGO'!$B:$B,0)+1),"")} -> 723162.81 | C8: =IFERROR(SUM(INDEX('JV RIEPILOGO'!$M:$M,MATCH($A8,'JV RIEPILOGO'!$B:$B,0)+2),INDEX('JV RIEPILOGO'!$M:$M,MATCH($A8,'JV RIEPILOGO'!$B:$B,0)+3)),"") -> 229618.19
A9: Total | B9: =SUM(B2:B8) -> 2.6833042e+08 | C9: =SUM(C2:C8) -> 2.3312743e+08
B10: =B9/'JV RIEPILOGO'!$M$32 -> 0.53510065 | C10: =C9/'JV RIEPILOGO'!$M$32 -> 0.46489935

Sheet JV RIEPILOGO
B1: ANALISI BUDGET WLOCLAWEK - MAG 26
C3: Budget Apertura | E3: B02 - Gennaio 2026 | G3: B7 - Febbraio 2026 | I3: B0 Riferimento (14) - Marzo 2026 | K3: B17 - Maggio 2026 | M3: B19 - Giugno 2026 | Q3: ORDINATO | R3: BUDGET | S3: 46143 | U3: 46174 | W3: 46204 | Y3: 46235 | AJ3: 46143 | AK3: 46174
B4: DESIGN | C4: ='1_Design'!C4+'1_Design'!C30 -> 45590000 | E4: =SUM(E5:E7) -> 45590000 | F4: =B4 -> DESIGN | G4: =SUM(G5:G7) -> 45590000 | I4: =SUM(I5:I7) -> 45590000 | K4: ='1_Design'!G4+'1_Design'!G30 -> 45590000 | M4: =SUM(M5:M7) -> 45590000 | Q4: =B4 -> DESIGN | R4: =M4 -> 45590000 | S4: 24397974 | T4: =S4/M4 -> 0.53516065 | U4: =M5 -> 24886974 | V4: =U4/M4 -> 0.54588669 | AI4: Costi Indiiretti | AJ4: =K34 -> 40036817 | AK4: 40357633
B5: Ordinato | C5: - | E5: 21990000 | F5: =B5 -> Ordinato | G5: 24270000 | H5: 0.8589476 | I5: ='1_Design'!$M$6 -> 24886974 | K5: ='1_Design'!G12+'1_Design'!G17+'1_Design'!G18+'1_Design'!G20+'1_Design'!G22+'1_Design'!G26+'1_Design'!G37 -> 24787974 | M5: ='1_Design'!$M$6 -> 24886974 | N5: =M5/M4 -> 0.54588669 | Q5: =B8 -> CIVIL WORKS | R5: =M8 -> 1.0810977e+08 | S5: 33404101 | T5: =S5/M8 -> 0.30898319 | U5: =M9 -> 53496524 | V5: =U5/M8 -> 0.49483526 | AI5: Costi di garanzia, difetti, imprevisti | AJ5: =K35 -> 22098535 | AK5: 22098535
B6: In negoziazione + buffer | C6: - | E6: =390000+17000000+150000 -> 17540000 | F6: =B6 -> In negoziazione + buffer | G6: 17890000 | H6: 0.042835399 | I6: ='1_Design'!$M$7 -> 17372026 | K6: ='1_Design'!G16+'1_Design'!G21+'1_Design'!G25+'1_Design'!G36+'1_Design'!G65 -> 17372026 | M6: ='1_Design'!$M$7 -> 17372026 | Q6: =B12 -> ELECTRICAL WORKS | R6: =M12 -> 58345340 | S6: 36070000 | T6: =S6/M12 -> 0.61821561 | U6: =M13 -> 36070000 | V6: =U6/M12 -> 0.61821561 | AI6: Totale Costi | AJ6: =AJ5+AJ4+R11 -> 5.6359321e+08 | AK6: =R11+AK4+AK5 -> 5.6391402e+08
B7: Da ordinare | C7: =C4 -> 45590000 | E7: 6060000 | F7: =B7 -> Da ordinare | G7: 3430000 | H7: 0.090889324 | I7: ='1_Design'!$M$8 -> 3331000 | K7: ='1_Design'!G19+'1_Design'!G23+'1_Design'!G24+'1_Design'!G32+'1_Design'!G41+'1_Design'!G45+'1_Design'!G49+'1_Design'!G53+'1_Design'!G57+'1_Design'!G61 -> 3430000 | M7: ='1_Design'!$M$8 -> 3331000 | Q7: =B16 -> SANITARY WORKS AND FF | R7: =M16 -> 21293319 | S7: 0 | T7: =S7/M16 -> 0 | U7: =M17 -> 0 | V7: =U7/M16 -> 0
B8: CIVIL WORKS | C8: ='2_Civil Work'!C3 -> 112409767 | E8: =SUM(E9:E11) -> 1.1240077e+08 | F8: =B8 -> CIVIL WORKS | G8: =SUM(G9:G11) -> 108109767 | I8: =SUM(I9:I11) -> 1.0810977e+08 | K8: ='2_Civil Work'!G3 -> 1.0810977e+08 | M8: =SUM(M9:M11) -> 1.0810977e+08 | Q8: =B20 -> MECHANICAL AND TECHNOLOGICAL | R8: =M20 -> 2.5866665e+08 | S8: 131227829 | T8: =S8/M20 -> 0.50732412 | U8: =M21 -> 1.5305376e+08 | V8: =U8/M20 -> 0.59170274 | AI8: Ricavi | AJ8: =K42 -> 627086000 | AK8: 627086000
B9: Ordinato | C9: - | E9: 9610714 | F9: =B9 -> Ordinato | G9: 25047291 | I9: ='2_Civil Work'!$M$5 -> 53496524 | K9: ='2_Civil Work'!G15+'2_Civil Work'!G20+'2_Civil Work'!G21+'2_Civil Work'!G22+'2_Civil Work'!G27+'2_Civil Work'!G34+'2_Civil Work'!G35+'2_Civil Work'!G36+'2_Civil Work'!G44+'2_Civil Work'!G47+'2_Civil Work'!G49+'2_Civil Work'!G50+'2_Civil Work'!G54+'2_Civil Work'!G57+'2_Civil Work'!G59+'2_Civil Work'!G60+'2_Civil Work'!G61+'2_Civil Work'!G69+'2_Civil Work'!G70+'2_Civil Work'!G72+'2_Civil Work'!G75+'2_Civil Work'!G121+'2_Civil Work'!G123+'2_Civil Work'!G149+'2_Civil Work'!G150 -> 53701520 | M9: ='2_Civil Work'!$M$5 -> 53496524 | N9: =M9/M8 -> 0.49483526 | Q9: =B24 -> COMMISSIONING | R9: =M24 -> 8500000 | S9: 100000 | T9: =S9/M24 -> 0.011764706 | U9: =M25 -> 100000 | V9: =U9/M24 -> 0.011764706 | AI9: Margine | AJ9: =AJ8-AJ6 -> 63492795 | AK9: =AK8-AK6 -> 63171979
B10: In negoziazione + buffer | C10: - | E10: =18700000+15345674 -> 34045674 | F10: =B10 -> In negoziazione + buffer | G10: 20510200 | I10: ='2_Civil Work'!$M$6 -> 16378807 | K10: ='2_Civil Work'!G12+'2_Civil Work'!G33+'2_Civil Work'!G42+'2_Civil Work'!G43+'2_Civil Work'!G46+'2_Civil Work'!G48+'2_Civil Work'!G53+'2_Civil Work'!G56+'2_Civil Work'!G68+'2_Civil Work'!G71+'2_Civil Work'!G74+'2_Civil Work'!G120+'2_Civil Work'!G122+'2_Civil Work'!G148 -> 16091828 | M10: ='2_Civil Work'!$M$6 -> 16378807 | Q10: =B28 -> ALIGNEMENT AND BACKUP | R10: =M28 -> 952781 | S10: =K29 -> 723162.81 | T10: =S10/M28 -> 0.75900213 | U10: =M29 -> 723162.81 | V10: =U10/M28 -> 0.75900213 | AJ10: =AJ9/AJ6 -> 0.11265713 | AK10: =AK9/AK6 -> 0.11202413
B11: Da ordinare | C11: =C8 -> 112409767 | E11: 68744379 | F11: =B11 -> Da ordinare | G11: 62552276 | I11: ='2_Civil Work'!$M$7 -> 38234436 | K11: ='2_Civil Work'!G26+'2_Civil Work'!G32+'2_Civil Work'!G55+'2_Civil Work'!G62+'2_Civil Work'!G63+'2_Civil Work'!G73+'2_Civil Work'!G79+'2_Civil Work'!G84+'2_Civil Work'!G85+'2_Civil Work'!G86+'2_Civil Work'!G87+'2_Civil Work'!G88+'2_Civil Work'!G89+'2_Civil Work'!G90+'2_Civil Work'!G91+'2_Civil Work'!G92+'2_Civil Work'!G93+'2_Civil Work'!G94+'2_Civil Work'!G95+'2_Civil Work'!G96+'2_Civil Work'!G101+'2_Civil Work'!G102+'2_Civil Work'!G103+'2_Civil Work'!G104+'2_Civil Work'!G105+'2_Civil Work'!G106+'2_Civil Work'!G110+'2_Civil Work'!G115+'2_Civil Work'!G116+'2_Civil Work'!G117+'2_Civil Work'!G118+'2_Civil Work'!G119+'2_Civil Work'!G124+'2_Civil Work'!G125+'2_Civil Work'!G126+'2_Civil Work'!G127+'2_Civil Work'!G128+'2_Civil Work'!G129+'2_Civil Work'!G130+'2_Civil Work'!G131+'2_Civil Work'!G132+'2_Civil Work'!G137+'2_Civil Work'!G138+'2_Civil Work'!G142+'2_Civil Work'!G147+'2_Civil Work'!G151+'2_Civil Work'!G155+'2_Civil Work'!G160+'2_Civil Work'!G161 -> 38316419 | M11: ='2_Civil Work'!$M$7 -> 38234436 | R11: =SUM(R4:R10) -> 5.0145785e+08 | S11: =SUM(S4:S10) -> 2.2592307e+08 | T11: =S11/M32 -> 0.45053251 | U11: =SUM(U4:U10) -> 2.6833042e+08 | V11: =U11/M32 -> 0.53510065
B12: ELECTRICAL WORKS | C12: ='3_Electrical Works'!C3 -> 58345340 | E12: =SUM(E13:E15) -> 58345340 | F12: =B12 -> ELECTRICAL WORKS | G12: =SUM(G13:G15) -> 58327340 | I12: =SUM(I13:I15) -> 58345340 | K12: ='3_Electrical Works'!G3 -> 58345340 | M12: =SUM(M13:M15) -> 58345340
B13: Ordinato | C13: - | E13: 0 | F13: =B13 -> Ordinato | G13: 38068200 | I13: ='3_Electrical Works'!$M$5 -> 36070000 | K13: ='3_Electrical Works'!G13+'3_Electrical Works'!G22+'3_Electrical Works'!G32 -> 36070000 | M13: ='3_Electrical Works'!$M$5 -> 36070000 | N13: =M13/M12 -> 0.61821561
B14: In negoziazione + buffer | C14: - | E14: 37400000 | F14: =B14 -> In negoziazione + buffer | G14: 0 | I14: ='3_Electrical Works'!$M$6 -> 2016200 | K14: =+'3_Electrical Works'!G12+'3_Electrical Works'!G31 -> 2016200 | M14: ='3_Electrical Works'!$M$6 -> 2016200
B15: Da ordinare | C15: =C12 -> 58345340 | E15: 20945340 | F15: =B15 -> Da ordinare | G15: 20259140 | I15: ='3_Electrical Works'!$M$7 -> 20259140 | K15: =+'3_Electrical Works'!G14+'3_Electrical Works'!G15+'3_Electrical Works'!G16+'3_Electrical Works'!G17+'3_Electrical Works'!G26+'3_Electrical Works'!G33+'3_Electrical Works'!G34 -> 20259140 | M15: ='3_Electrical Works'!$M$7 -> 20259140
B16: SANITARY WORKS AND FF | C16: ='4_Sanitary works and FF'!C3 -> 21293319 | E16: 21293319 | F16: =B16 -> SANITARY WORKS AND FF | G16: =SUM(G17:G19) -> 21293319 | I16: =SUM(I17:I19) -> 21293319 | K16: 21293319 | M16: =SUM(M17:M19) -> 21293319
B17: Ordinato | C17: - | E17: 0 | F17: =B17 -> Ordinato | G17: 0 | I17: ='4_Sanitary works and FF'!$M$6 -> 0 | K17: 0 | M17: ='4_Sanitary works and FF'!$M$6 -> 0 | N17: =M17/M16 -> 0
B18: In negoziazione + buffer | C18: - | E18: 0 | F18: =B18 -> In negoziazione + buffer | G18: 0 | I18: ='4_Sanitary works and FF'!$M$7 -> 0 | K18: 0 | M18: ='4_Sanitary works and FF'!$M$7 -> 0
B19: Da ordinare | C19: =C16 -> 21293319 | E19: 21293319 | F19: =B19 -> Da ordinare | G19: 21293319 | I19: ='4_Sanitary works and FF'!$M$8 -> 21293319 | K19: 21293319 | M19: ='4_Sanitary works and FF'!$M$8 -> 21293319
B20: MECHANICAL AND TECHNOLOGICAL | C20: ='5_Mechanical and technological'!C3 -> 258666646 | E20: =SUM(E21:E23) -> 2.5866665e+08 | F20: =B20 -> MECHANICAL AND TECHNOLOGICAL | G20: =SUM(G21:G23) -> 258666646 | I20: =SUM(I21:I23) -> 2.5866665e+08 | K20: 2.5866665e+08 | M20: =SUM(M21:M23) -> 2.5866665e+08
B21: Ordinato | C21: - | E21: 67510000 | F21: =B21 -> Ordinato | G21: 67810000 | I21: ='5_Mechanical and technological'!$M$5 -> 1.5305376e+08 | K21: ='5_Mechanical and technological'!G17+'5_Mechanical and technological'!G23+'5_Mechanical and technological'!G36+'5_Mechanical and technological'!G41+'5_Mechanical and technological'!G59+'5_Mechanical and technological'!G80+'5_Mechanical and technological'!G103+'5_Mechanical and technological'!G127 -> 1.3122783e+08 | M21: ='5_Mechanical and technological'!$M$5 -> 1.5305376e+08 | N21: =M21/M20 -> 0.59170274
B22: In negoziazione + buffer | C22: - | E22: =700000+300000 -> 1000000 | F22: =B22 -> In negoziazione + buffer | G22: 85700000 | I22: ='5_Mechanical and technological'!$M$6 -> 6615898 | K22: ='5_Mechanical and technological'!G35+'5_Mechanical and technological'!G79+'5_Mechanical and technological'!G102+'5_Mechanical and technological'!G126 -> 9211113.9 | M22: ='5_Mechanical and technological'!$M$6 -> 6615898
B23: Da ordinare | C23: =C20 -> 258666646 | E23: 1.9015665e+08 | F23: =B23 -> Da ordinare | G23: 105156646 | I23: ='5_Mechanical and technological'!$M$7 -> 98996985 | K23: =+'5_Mechanical and technological'!G12+'5_Mechanical and technological'!G18+'5_Mechanical and technological'!G24+'5_Mechanical and technological'!G25+'5_Mechanical and technological'!G26+'5_Mechanical and technological'!G27+'5_Mechanical and technological'!G28+'5_Mechanical and technological'!G29+'5_Mechanical and technological'!G30+'5_Mechanical and technological'!G42+'5_Mechanical and technological'!G43+'5_Mechanical and technological'!G44+'5_Mechanical and technological'!G45+'5_Mechanical and technological'!G49+'5_Mechanical and technological'!G53+'5_Mechanical and technological'!G58+'5_Mechanical and technological'!G60+'5_Mechanical and technological'!G61+'5_Mechanical and technological'!G66+'5_Mechanical and technological'!G67+'5_Mechanical and technological'!G68+'5_Mechanical and technological'!G72+'5_Mechanical and technological'!G77+'5_Mechanical and technological'!G78+'5_Mechanical and technological'!G81+'5_Mechanical and technological'!G82+'5_Mechanical and technological'!G83+'5_Mechanical and technological'!G84+'5_Mechanical and technological'!G85+'5_Mechanical and technological'!G86+'5_Mechanical and technological'!G87+'5_Mechanical and technological'!G88+'5_Mechanical and technological'!G89+'5_Mechanical and technological'!G90+'5_Mechanical and technological'!G91+'5_Mechanical and technological'!G92+'5_Mechanical and technological'!G94+'5_Mechanical and technological'!G95+'5_Mechanical and technological'!G96+'5_Mechanical and technological'!G97+'5_Mechanical and technological'!G98+'5_Mechanical and technological'!G107+'5_Mechanical and technological'!G112+'5_Mechanical and technological'!G113+'5_Mechanical and technological'!G114+'5_Mechanical and technological'!G115+'5_Mechanical and technological'!G116+'5_Mechanical and technological'!G117+'5_Mechanical and technological'!G118+'5_Mechanical and technological'!G119+'5_Mechanical and technological'!G120+'5_Mechanical and technological'!G121+'5_Mechanical and technological'!G128+'5_Mechanical and technological'!G129+'5_Mechanical and technological'!G130 -> 1.182277e+08 | M23: ='5_Mechanical and technological'!$M$7 -> 98996985
B24: COMMISSIONING | C24: ='6_ Commissioning'!C3 -> 8500000 | E24: =SUM(E25:E27) -> 8500000 | F24: =B24 -> COMMISSIONING | G24: =SUM(G25:G27) -> 8500000 | I24: =SUM(I25:I27) -> 8500000 | K24: =+'6_ Commissioning'!G3 -> 8500000 | M24: =SUM(M25:M27) -> 8500000
B25: Ordinato | C25: - | E25: 0 | F25: =B25 -> Ordinato | G25: 500000 | I25: ='6_ Commissioning'!$M$5 -> 100000 | K25: =+'6_ Commissioning'!G35 -> 100000 | M25: ='6_ Commissioning'!$M$5 -> 100000 | N25: =M25/M24 -> 0.011764706
B26: In negoziazione + buffer | C26: - | E26: 0 | F26: =B26 -> In negoziazione + buffer | G26: 0 | I26: ='6_ Commissioning'!$M$6 -> 400000 | K26: =+'6_ Commissioning'!G34 -> 400000 | M26: ='6_ Commissioning'!$M$6 -> 400000
B27: Da ordinare | C27: =C24 -> 8500000 | E27: 8500000 | F27: =B27 -> Da ordinare | G27: 8000000 | I27: ='6_ Commissioning'!$M$7 -> 8000000 | K27: =+'6_ Commissioning'!G12+'6_ Commissioning'!G13+'6_ Commissioning'!G14+'6_ Commissioning'!G15+'6_ Commissioning'!G20+'6_ Commissioning'!G21+'6_ Commissioning'!G22+'6_ Commissioning'!G23+'6_ Commissioning'!G24+'6_ Commissioning'!G25+'6_ Commissioning'!G26+'6_ Commissioning'!G30+'6_ Commissioning'!G39+'6_ Commissioning'!G43 -> 8000000 | M27: ='6_ Commissioning'!$M$7 -> 8000000
B28: ALIGNEMENT AND BACKUP | C28: ='7_Backup'!C3 -> 952781 | E28: =SUM(E29:E31) -> 952781 | F28: =B28 -> ALIGNEMENT AND BACKUP | G28: =SUM(G29:G31) -> 952781 | I28: =SUM(I29:I31) -> 952781 | K28: =+'7_Backup'!G3 -> 952781 | M28: =SUM(M29:M31) -> 952781
B29: Ordinato | C29: - | E29: =322212.81+400000 -> 722212.81 | F29: =B29 -> Ordinato | G29: 723163 | I29: ='7_Backup'!$M$5 -> 723162.81 | K29: ='7_Backup'!$M$5 -> 723162.81 | M29: ='7_Backup'!$M$5 -> 723162.81 | N29: =M29/M28 -> 0.75900213
B30: In negoziazione + buffer | C30: - | E30: 0 | F30: =B30 -> In negoziazione + buffer | G30: 0 | I30: ='7_Backup'!$M$6 -> 229618.19 | K30: =+'7_Backup'!G11+'7_Backup'!G16 -> 229618.19 | M30: ='7_Backup'!$M$6 -> 229618.19
B31: Da ordinare | C31: =C28 -> 952781 | E31: =216139.19+14429 -> 230568.19 | F31: =B31 -> Da ordinare | G31: 229618 | I31: ='7_Backup'!$M$9 -> 0 | K31: 0 | M31: ='7_Backup'!$M$9 -> 0
B32: Diretti | C32: =C4+C8+C12+C16+C20+C24+C28 -> 505757853 | E32: =E4+E8+E12+E16+E20+E24+E28 -> 5.0574885e+08 | F32: =B32 -> Diretti | G32: 5.0615785e+08 | I32: =I4+I8+I12+I16+I20+I24+I28 -> 5.0145785e+08 | K32: =+K28+K24+K20+K16+K12+K8+K4 -> 5.0145785e+08 | M32: =M4+M8+M12+M16+M20+M24+M28 -> 5.0145785e+08 | Q32: 40357633
B34: Indiretti | C34: ='0_Indirect'!C3 -> 40391014 | E34: ='0_Indirect'!D3 -> 40391014 | G34: 40386273 | I34: 40355205 | K34: 40036817 | M34: ='0_Indirect'!H3 -> 40357635
B35: Manutenzione | C35: 0 | E35: 22098535 | G35: 22098535 | I35: 22098535 | K35: 22098535 | M35: 22098535
B36: Totale Costi | C36: =C32+C34 -> 5.4614887e+08 | E36: =E32+E34+E35 -> 5.682384e+08 | G36: =G32+G34+G35 -> 5.6864266e+08 | I36: =I32+I34+I35 -> 5.6391159e+08 | K36: 5.6359321e+08 | M36: =M32+M34+M35 -> 5.6391402e+08 | O36: =M36/4.25 -> 1.3268565e+08 | P36: =O36*0.2 -> 26537131
C38: Totale ordinato | E38: =E29+E25+E21+E17+E13+E9+E5 -> 99832927 | F38: =E38/$E$32 -> 0.19739625 | G38: =G29+G25+G21+G17+G13+G9+G5 -> 156418654 | H38: 0.30494131 | I38: =I29+I25+I21+I17+I14+I9+I5 -> 2.3427662e+08 | J38: =I38/$I$32 -> 0.46719106 | K38: 2.6833042e+08 | M38: =M29+M25+M21+M17+M13+M9+M5 -> 2.6833042e+08 | N38: =M38/M32 -> 0.53510065
C39: Totale in neg + buffer | E39: =E6+E10+E14+E18+E22+E26+E30 -> 89985674 | G39: =G6+G10+G14+G18+G22+G26+G30 -> 124100200 | K39: 43012549 | M39: =M6+M10+M14+M18+M22+M26+M30 -> 43012549 | N39: =M39/M32 -> 0.085775003
C40: Totale da ordinare | E40: =E7+E11+E15+E19+E23+E27+E31 -> 3.1593025e+08 | F40: =E40/$E$32 -> 0.62467814 | G40: =G7+G11+G15+G19+G23+G27+G31 -> 220920999 | H40: 0.61558488 | I40: =I31+I27+I23+I19+I15+I11+I7 -> 1.9011488e+08 | J40: =I40/$I$32 -> 0.37912434 | K40: 1.9011488e+08 | M40: =M7+M11+M15+M19+M23+M27+M31 -> 1.9011488e+08 | N40: =M40/M32 -> 0.37912434
B42: Ricavi Base | C42: 631386000 | E42: 631386000 | G42: 6.31386e+08 | I42: 627086000 | K42: 627086000 | M42: 627086000 | O42: =M42/4.21 -> 1.4895154e+08 | P42: =O42*0.2 -> 29790309
B44: Margine | C44: =C42-C36 -> 85237133 | D44: =C44/C36 -> 0.15606941 | E44: =E42-E36 -> 63147598 | F44: =E44/E36 -> 0.1111287 | G44: 62743338 | H44: =G44/G36 -> 0.11033878 | I44: =I42-I36 -> 63174407 | J44: =I44/I36 -> 0.11202892 | K44: 63492795 | M44: =M42-M36 -> 63171977 | N44: =M44/M36 -> 0.11202413 | O44: =M44/4.25 -> 14863995 | P44: =O44*0.2 -> 2972798.9 | Q44: =P44/P36 -> 0.11202413

Sheet INTERNA
C2: 2025 | D2: 2026 | E2: oltre
B3: produzione | C3: =+C4+C5 -> 244.46201 | D3: =+D4+D5 -> 8888 | E3: =+E4+E5 -> 13414.595
B4: costi | C4: =+('[1]Włocławek Budget'!AM403+'[1]Włocławek Budget'!AM391)/4.2*0.15/1000 -> 220.03781 | D4: =+_xlfn.FLOOR.MATH(SUM('[1]Włocławek Budget'!AN403:AY403)/4.2*0.15/1000,1000) -> 8000 | E4: =+('[1]Włocławek Budget'!AB403/4.2*0.15/1000)-D4-C4 -> 12074.343
B5: margine | C5: =+C4*C6 -> 24.424197 | D5: =+D4*D6 -> 888 | E5: =+E4*E6 -> 1340.2521
B6: % | C6: =+D6 -> 0.111 | D6: 0.111 | E6: =+D6 -> 0.111

Sheet Report
C4: Bdgt apertura | D4: B02 - Gen26 | E4: B07 - Feb26 | P4: Consorzio | Q4: PORR 80%
B5: Costi diretti | C5: ='JV RIEPILOGO'!C32 -> 505757853 | D5: ='JV RIEPILOGO'!E32 -> 5.0574885e+08 | E5: ='JV RIEPILOGO'!I32 -> 5.0145785e+08 | Q5: TME 20%
B6: Costi indiretti | C6: ='JV RIEPILOGO'!C34 -> 40391014 | D6: ='JV RIEPILOGO'!E34 -> 40391014 | E6: ='JV RIEPILOGO'!I34 -> 40355205
B7: Contingency | C7: ='JV RIEPILOGO'!C35 -> 0 | D7: ='JV RIEPILOGO'!E35 -> 22098535 | E7: ='JV RIEPILOGO'!I35 -> 22098535 | P7: Cliente | Q7: PreZero
B8: Totale costi | C8: ='JV RIEPILOGO'!C36 -> 5.4614887e+08 | D8: ='JV RIEPILOGO'!E36 -> 5.682384e+08 | E8: ='JV RIEPILOGO'!I36 -> 5.6391159e+08
B9: Ricavi base | C9: ='JV RIEPILOGO'!C42 -> 631386000 | D9: ='JV RIEPILOGO'!E42 -> 631386000 | E9: ='JV RIEPILOGO'!I42 -> 627086000 | P9: Inizio progetto | Q9: 46052
B10: Margine | C10: ='JV RIEPILOGO'!C44 -> 85237133 | D10: ='JV RIEPILOGO'!E44 -> 63147598 | E10: ='JV RIEPILOGO'!I44 -> 63174407
B11: % | C11: =C10/C9 -> 0.13500004 | D11: =D10/D9 -> 0.10001425 | E11: =E10/E9 -> 0.10074281 | P11: Fine progetto | Q11: 46934
H15: COSTI DIRETTI (PLN)
I16: Apertura | J16: B07 | L16: Dettaglio costi diretti
H17: DESIGN | I17: ='JV RIEPILOGO'!C4 -> 45590000 | J17: ='JV RIEPILOGO'!I4 -> 45590000 | L17: Ordinato totale (senza TME) | M17: ='JV RIEPILOGO'!I5+'JV RIEPILOGO'!I9+'JV RIEPILOGO'!I13+'JV RIEPILOGO'!I17+'JV RIEPILOGO'!I21+'JV RIEPILOGO'!I25+'JV RIEPILOGO'!I29-M18 -> 1.9093042e+08 | N17: =M17/SUM($M$17:$M$21) -> #REF!
H18: CIVIL WORKS | I18: ='JV RIEPILOGO'!C8 -> 112409767 | J18: ='JV RIEPILOGO'!I8 -> 1.0810977e+08 | L18: Ordini a TME | M18: =Ordinato!C4 -> 77400000 | N18: =M18/SUM($M$17:$M$21) -> #REF!
H19: ELECTRICAL WORKS | I19: ='JV RIEPILOGO'!C12 -> 58345340 | J19: ='JV RIEPILOGO'!I12 -> 58345340 | L19: Negoziazioni totale | M19: ='JV RIEPILOGO'!I6+'JV RIEPILOGO'!I10+'JV RIEPILOGO'!I14+'JV RIEPILOGO'!I18+'JV RIEPILOGO'!I22+'JV RIEPILOGO'!I26+'JV RIEPILOGO'!I30 -> 43012549 | N19: =M19/SUM($M$17:$M$21) -> #REF!
H20: SANITARY WORKS AND FF | I20: ='JV RIEPILOGO'!E16 -> 21293319 | J20: ='JV RIEPILOGO'!I16 -> 21293319 | L20: Pianificato totale | M20: ='JV RIEPILOGO'!I7+'JV RIEPILOGO'!I11+'JV RIEPILOGO'!I15+'JV RIEPILOGO'!I19+'JV RIEPILOGO'!I23+'JV RIEPILOGO'!I27+'JV RIEPILOGO'!I31 -> 1.9011488e+08 | N20: =M20/SUM($M$17:$M$21) -> #REF!
H21: MECHANICAL AND TECHNOLOGICAL | I21: ='JV RIEPILOGO'!E20 -> 2.5866665e+08 | J21: ='JV RIEPILOGO'!I20 -> 2.5866665e+08 | L21: Buffer totale | M21: ='JV RIEPILOGO'!#REF!+'JV RIEPILOGO'!#REF!+'JV RIEPILOGO'!#REF!+'JV RIEPILOGO'!#REF!+'JV RIEPILOGO'!#REF!+'JV RIEPILOGO'!#REF!+'JV RIEPILOGO'!#REF! -> #REF! | N21: =M21/SUM($M$17:$M$21) -> #REF!
H22: COMMISSIONING | I22: ='JV RIEPILOGO'!C24 -> 8500000 | J22: ='JV RIEPILOGO'!I24 -> 8500000 | M22: =SUM(M17:M21) -> #REF!
H23: ALIGNEMENT AND BACKUP | I23: ='JV RIEPILOGO'!C28 -> 952781 | J23: ='JV RIEPILOGO'!I28 -> 952781
I24: =SUM(I17:I23) -> 5.0575785e+08 | J24: =SUM(J17:J23) -> 5.0145785e+08
H26: COSTI INDIRETTI (PLN) | L26: Lista ordini/ negoziazioni
I27: Apertura | J27: B07 | L27: Fornitore | M27: Sezione | N27: Item | O27: Descrizione | P27: Ordine | Q27: Importo
H28: STAFF | I28: ='0_Indirect'!C10 -> 29056500 | J28: ='0_Indirect'!E10 -> 29056500 | L28: =Ordinato!B28 -> FOROOM | M28: =Ordinato!C28 -> 1_Design | N28: =Ordinato!D28 -> 1.2.1 | O28: =Ordinato!E28 -> Detailed architectural, structural, sanitary and road designs | P28: =Ordinato!F28 -> 4502938068 | Q28: =Ordinato!G28 -> 12100000
H29: EQUIPMENT | I29: ='0_Indirect'!C18 -> 2404000 | J29: ='0_Indirect'!E18 -> 2404000 | L29: =Ordinato!B29 -> THYSSENKRUPP MATERIALS POLAND S.A. | M29: =Ordinato!C29 -> 2_Civil Works | N29: =Ordinato!D29 -> 2.5.1.1.1 | O29: =Ordinato!E29 -> Supply of reinforcing steel | P29: =Ordinato!F29 -> 4502938804 | Q29: =Ordinato!G29 -> 1821319
H30: CONSTRUCTION OFFICE | I30: ='0_Indirect'!C61 -> 4216821 | J30: ='0_Indirect'!E61 -> 4216821 | L30: =Ordinato!B30 -> THYSSENKRUPP MATERIALS POLAND S.A. | M30: =Ordinato!C30 -> 2_Civil Works | N30: =Ordinato!D30 -> 2.5.2.3.1 | O30: =Ordinato!E30 -> Supply of reinforcing steel | P30: =Ordinato!F30 -> 4502938804 | Q30: =Ordinato!G30 -> 1602761
H31: CONSTRUCTION | I31: ='0_Indirect'!C158 -> 3767010 | J31: ='0_Indirect'!E158 -> 3767010 | L31: =Ordinato!B31 -> MAR-KOP Marcin Mierzwa | M31: =Ordinato!C31 -> 2_Civil Works | N31: =Ordinato!D31 -> 2.2.1 | O31: =Ordinato!E31 -> Working platform for foundation works | P31: =Ordinato!F31 -> 4502939064 | Q31: =Ordinato!G31 -> 176673
H32: INSTALLATION / UNINSTALLATION OF CONSTRUCTION | I32: ='0_Indirect'!C222 -> 2278160 | J32: ='0_Indirect'!E222 -> 2278160 | L32: =Ordinato!B32 -> MAR-KOP Marcin Mierzwa | M32: =Ordinato!C32 -> 2_Civil Works | N32: =Ordinato!D32 -> 2.2.2 | O32: =Ordinato!E32 -> Earthworks | P32: =Ordinato!F32 -> 4502939064 | Q32: =Ordinato!G32 -> 2196542
H33: MISCELLANEOUS COSTS | I33: ='0_Indirect'!C270 -> 1600208 | J33: ='0_Indirect'!E270 -> 1600208 | L33: =Ordinato!B33 -> MAR-KOP Marcin Mierzwa | M33: =Ordinato!C33 -> 2_Civil Works | N33: =Ordinato!D33 -> 2.2.3 | O33: =Ordinato!E33 -> Earthworks – backfilling of retaining wall | P33: =Ordinato!F33 -> 4502939064 | Q33: =Ordinato!G33 -> 313419
H34: FINANCIAL COSTS | I34: ='0_Indirect'!C305 -> -2931684.9 | J34: ='0_Indirect'!E305 -> -2936425.7 | L34: =Ordinato!B34 -> MAR-KOP Marcin Mierzwa | M34: =Ordinato!C34 -> 7_Backup | N34: =Ordinato!D34 -> 7.1.1 | O34: =Ordinato!E34 -> Earthmoving robots ECR 3 | P34: =Ordinato!F34 -> 4502939064 | Q34: =Ordinato!G34 -> 322212.81
B35: Dati: Budget B07 di Febbraio 2026 | I35: =SUM(I28:I34) -> 40391014 | J35: =SUM(J28:J34) -> 40386273 | L35: =Ordinato!B35 -> KaBo | M35: =Ordinato!C35 -> 7_Backup | N35: =Ordinato!D35 -> 8.1.2 | O35: =Ordinato!E35 -> Obtaining ECR 4 decisions and permits | P35: =Ordinato!F35 -> 4502946461 | Q35: =Ordinato!G35 -> 400000
L36: =Ordinato!B36 -> ZAKŁAD SOZOTECHNIKI | M36: =Ordinato!C36 -> 1_Design | N36: =Ordinato!D36 -> 1.2.7.1 | O36: =Ordinato!E36 -> Preparation of an application for an integrated permit, together with all necessary documents. | P36: =Ordinato!F36 -> 4502966963 | Q36: =Ordinato!G36 -> 113000
L37: =Ordinato!B37 -> BARG | M37: =Ordinato!C37 -> 2_Civil Works | N37: =Ordinato!D37 -> 2.5.1.1.2 | O37: =Ordinato!E37 -> Concrete testing | P37: =Ordinato!F37 -> 4502968920 | Q37: =Ordinato!G37 -> 131560
L38: =Ordinato!B38 -> PROJBUD | M38: =Ordinato!C38 -> 7_Backup | N38: =Ordinato!D38 -> 8.1.1 | O38: =Ordinato!E38 -> Temporary traffic organization ECD 34 | P38: =Ordinato!F38 -> 4502971480 | Q38: =Ordinato!G38 -> 950
L39: =Ordinato!B43 -> Stump-Franki Sp. z o.o. | M39: =Ordinato!C43 -> 2_Civil Works | N39: =Ordinato!D43 -> 2.1.2 | O39: =Ordinato!E43 -> Diaphragm wall and barrettes part 1 | P39: =Ordinato!F43 -> ok | Q39: =Ordinato!G43 -> 3176000
L40: =Ordinato!B44 -> Stump-Franki Sp. z o.o. | M40: =Ordinato!C44 -> 2_Civil Works | N40: =Ordinato!D44 -> 2.1.3 | O40: =Ordinato!E44 -> Barrettes part 2 | P40: =Ordinato!F44 -> ok | Q40: =Ordinato!G44 -> 1124000
Q41: =SUM(Q28:Q40) -> 23478437
L43: =Ordinato!B52 -> TM.E. S.p.A - Termomeccanica Ecologia | M43: =Ordinato!C52 -> 5_Mechanical & Tech. | N43: =Ordinato!D52 -> 5.3.1 | O43: =Ordinato!E52 -> Furnace charging hopper + Furnace supporting steel structure + Complete grate fired furnace with waste feeding system + Hoppers under grate | P43: =Ordinato!F52 -> ok | Q43: =Ordinato!G52 -> 33755000
L44: =Ordinato!B53 -> TM.E. S.p.A - Termomeccanica Ecologia | M44: =Ordinato!C53 -> 5_Mechanical & Tech. | N44: =Ordinato!D53 -> 5.7.2 | O44: =Ordinato!E53 -> Flue gas treatment (FGT): Bag filter, Reactor, DeNOx, Flue gas condensation, Lime and activated carbon silos, dosing system | P44: =Ordinato!F53 -> ok | Q44: =Ordinato!G53 -> 33755000
L45: =Ordinato!B39 -> TME | M45: =Ordinato!C39 -> 1_Design | N45: =Ordinato!D39 -> 1.1 | O45: =Ordinato!E39 -> TME design | P45: =Ordinato!F39 -> ok | Q45: =Ordinato!G39 -> 9890000
Q46: =SUM(Q43:Q45) -> 77400000
L48: =Ordinato!B40 -> ELEKTROSERV - ZAP | M48: =Ordinato!C40 -> 1_Design | N48: =Ordinato!D40 -> 1.2.4 | O48: =Ordinato!E40 -> Electrical & I/C detailed design | P48: =Ordinato!F40 -> 0 | Q48: =Ordinato!G40 -> 1580000
L49: =Ordinato!B49 -> ELEKTROSERV - ZAP | M49: =Ordinato!C49 -> 3_Electrical Works | N49: =Ordinato!D49 -> 3.1.1.1 | O49: =Ordinato!E49 -> Delivery and installation of electrical equipment | P49: =Ordinato!F49 -> 0 | Q49: =Ordinato!G49 -> 28282000
...

Sheet Ordinato
B2: Totale costi | C2: ='JV RIEPILOGO'!I32 -> 5.0145785e+08
B3: Totale ordinato/negoziazione | C3: =SUM(C8:C23) -> 1.7990855e+08 | D3: =C3/C2 -> 0.35877102
B4: TME | C4: =C9+C8 -> 77400000 | D4: =C4/$C$3 -> 0.43021858
B5: Chiusi | C5: =G28+G29+G31+G30+G32+G33+G35+G34+G36+G37+G38 -> 19178437 | D5: =C5/$C$3 -> 0.10660103
B6: Negoziazione | C6: =G40+G41+G42+G43+G44+G45+G46+G47+G48+G49+G50+G51+G54+G55 -> 83330109 | D6: =C6/$C$3 -> 0.46318038
B8: TME | C8: =SUMIF($B$28:$B$5004,B8,$G$28:$G$5003) -> 9890000 | D8: =C8/$C$3 -> 0.054972375
B9: TM.E. S.p.A - Termomeccanica Ecologia | C9: =SUMIF($B$28:$B$5004,B9,$G$28:$G$5003) -> 67510000 | D9: =C9/$C$3 -> 0.37524621
B11: FOROOM | C11: =SUMIF($B$28:$B$5004,B11,$G$28:$G$5003) -> 12100000 | D11: =C11/$C$3 -> 0.067256394
B12: ELEKTROSERV - ZAP | C12: =SUMIF($B$28:$B$5004,B12,$G$28:$G$5003) -> 37750000 | D12: =C12/$C$3 -> 0.20982883 | E12: Lump sum
B13: MENOS | C13: =SUMIF($B$28:$B$5004,B13,$G$28:$G$5003) -> 390000 | D13: =C13/$C$3 -> 0.0021677681
B14: ZAKŁAD SOZOTECHNIKI | C14: =SUMIF($B$28:$B$5004,B14,$G$28:$G$5003) -> 113000 | D14: =C14/$C$3 -> 0.0006280969
B15: KaBo | C15: =SUMIF($B$28:$B$5004,B15,$G$28:$G$5003) -> 17400000 | D15: =C15/$C$3 -> 0.096715806
B16: Stump-Franki Sp. z o.o. | C16: =SUMIF($B$28:$B$5004,B16,$G$28:$G$5003) -> 4300000 | D16: =C16/$C$3 -> 0.023901032
B17: MAR-KOP Marcin Mierzwa | C17: =SUMIF($B$28:$B$5004,B17,$G$28:$G$5003) -> 3008846.8 | D17: =C17/$C$3 -> 0.016724313
B18: THYSSENKRUPP MATERIALS POLAND S.A. | C18: =SUMIF($B$28:$B$5004,B18,$G$28:$G$5003) -> 3424080 | D18: =C18/$C$3 -> 0.019032337
B19: BARG | C19: =SUMIF($B$28:$B$5004,B19,$G$28:$G$5003) -> 131560 | D19: =C19/$C$3 -> 0.00073126043
B20: BUSZREM | C20: =SUMIF($B$28:$B$5004,B20,$G$28:$G$5003) -> 4490109 | D20: =C20/$C$3 -> 0.024957731
B21: BETARD | C21: =SUMIF($B$28:$B$5004,B21,$G$28:$G$5003) -> 18700000 | D21: =C21/$C$3 -> 0.1039417
B22: AS Rusztowania | C22: =SUMIF($B$28:$B$5004,B22,$G$28:$G$5003) -> 700000 | D22: =C22/$C$3 -> 0.0038908658
B23: PROJBUD | C23: =SUMIF($B$28:$B$5004,B23,$G$28:$G$5003) -> 950 | D23: =C23/$C$3 -> 5.2804607e-06
B27: Fornitore | C27: Macroattività | D27: Item | E27: Descrizione | F27: Ordine | G27: Importo
B28: FOROOM | C28: 1_Design | D28: 1.2.1 | E28: Detailed architectural, structural, sanitary and road designs | F28: 4502938068 | G28: 12100000
B29: THYSSENKRUPP MATERIALS POLAND S.A. | C29: 2_Civil Works | D29: 2.5.1.1.1 | E29: Supply of reinforcing steel | F29: 4502938804 | G29: 1821319
B30: THYSSENKRUPP MATERIALS POLAND S.A. | C30: 2_Civil Works | D30: 2.5.2.3.1 | E30: Supply of reinforcing steel | F30: 4502938804 | G30: 1602761
B31: MAR-KOP Marcin Mierzwa | C31: 2_Civil Works | D31: 2.2.1 | E31: Working platform for foundation works | F31: 4502939064 | G31: 176673
B32: MAR-KOP Marcin Mierzwa | C32: 2_Civil Works | D32: 2.2.2 | E32: Earthworks | F32: 4502939064 | G32: 2196542
B33: MAR-KOP Marcin Mierzwa | C33: 2_Civil Works | D33: 2.2.3 | E33: Earthworks – backfilling of retaining wall | F33: 4502939064 | G33: 313419
B34: MAR-KOP Marcin Mierzwa | C34: 7_Backup | D34: 7.1.1 | E34: Earthmoving robots ECR 3 | F34: 4502939064 | G34: 322212.81
B35: KaBo | C35: 7_Backup | D35: 8.1.2 | E35: Obtaining ECR 4 decisions and permits | F35: 4502946461 | G35: 400000
B36: ZAKŁAD SOZOTECHNIKI | C36: 1_Design | D36: 1.2.7.1 | E36: Preparation of an application for an integrated permit, together with all necessary documents. | F36: 4502966963 | G36: 113000
B37: BARG | C37: 2_Civil Works | D37: 2.5.1.1.2 | E37: Concrete testing | F37: 4502968920 | G37: 131560 | H37: =SUM(G29:G37) -> 7077486.8
B38: PROJBUD | C38: 7_Backup | D38: 8.1.1 | E38: Temporary traffic organization ECD 34 | F38: 4502971480 | G38: 950
B39: TME | C39: 1_Design | D39: 1.1 | E39: TME design | F39: ok | G39: 9890000
B40: ELEKTROSERV - ZAP | C40: 1_Design | D40: 1.2.4 | E40: Electrical & I/C detailed design | G40: 1580000
B41: MENOS | C41: 1_Design | D41: 1.2.5.1 | E41: Building and detailed design of the GPO/GPZ station | G41: 390000
B42: KaBo | C42: 1_Design | D42: 1.11 | E42: Obtaining decisions and permits | G42: 17000000
B43: Stump-Franki Sp. z o.o. | C43: 2_Civil Works | D43: 2.1.2 | E43: Diaphragm wall and barrettes part 1 | F43: ok | G43: 3176000
B44: Stump-Franki Sp. z o.o. | C44: 2_Civil Works | D44: 2.1.3 | E44: Barrettes part 2 | F44: ok | G44: 1124000
B45: BUSZREM | C45: 2_Civil Works | D45: 2.5.1.2 | E45: Supply of concrete mix with pumping service | G45: 3420000
B46: BETARD | C46: 2_Civil Works | D46: 2.5.2.1.1 | E46: Reinforced concrete structure of the above-ground part of the B1 building - delivery and assembly of prefabricated elements | G46: 18700000
...

Sheet 0_Indirect
C2: BUDGET APERTURA | D2: BUDGET 02 | E2: BUDGET 07 | F2: BUDGET 14 (B0 approvato Mar 26) | G2: BUDGET 17 | H2: BUDGET 19 | J2: =SUM(J5:J7) -> 40357635
A3: 0 | B3: INDIRECT | C3: =C10+C18+C61+C158+C222+C270+C305 -> 40391014 | D3: =D10+D18+D61+D158+D222+D270+D305 -> 40391014 | E3: =E10+E18+E61+E158+E222+E270+E305 -> 40386273 | F3: =F10+F18+F61+F158+F222+F270+F305 -> 40355205 | G3: =G10+G18+G61+G158+G222+G270+G305 -> 40036817 | H3: =H10+H18+H61+H158+H222+H270+H305 -> 40357635
G4: =$F$3-G3 -> 318387.43 | H4: =$F$3-H3 -> -2430.3576
I5: Ordered | J5: =H13+H14+H22+H27+H28+H42+H43+H65+H67+H74+H79+H96+H107+H108+H109+H122+H135+H140+H146+H150+H166+H182+H187+H197+H201+H205+H226+H232+H233+H235+H236+H237+H244+H245+H255+H278+H279+H285+H300+H301+H314+H57+H55+H54+H53+H29+H30+H31+H32+H101+H167+H66+H254+H33+H34+H35+H36+H37+H44+H68+H69+H102+H123+H131+H141+H142+H168+H173+H188+H193+H210+H238+H256+H257+H258+H284+H294 -> 36343126
I6: Negotiation+buffer | J6: =+H26+H41+H52+H64+H73+H78+H95+H100+H106+H121+H139+H165+H172+H181+H186+H192+H231+H234+H253+H277+H283+H299+H312 -> 3545713
I7: Planned | J7: =+H21+H48+H83+H87+H91+H117+H127+H154+H161+H177+H209+H214+H249+H262+H266+H273+H289+H293+H298+H313+H318+H326+H330+H334+H338+H339 -> 468796.15
I8: (Buffer) | J8: =+H26+H41+H52+H64+H73+H78+H95+H100+H106+H121+H139+H165+H172+H181+H186+H192+H231+H234+H253+H277+H283+H299+H312 -> 3545713
A10: 1 | B10: STAFF | C10: =C15 -> 29056500 | D10: =D15 -> 29056500 | E10: =E15 -> 29056500 | F10: =F15 -> 29056500 | G10: =G15 -> 28713000 | H10: =H15 -> 29017400
G11: =G10-$F10 -> -343500 | H11: =H10-$F10 -> -39100
A13: 1.1 | B13: Remuneration PORR | C13: 18824500 | D13: 18824500 | E13: 18824500 | F13: 18824500 | G13: 18481000 | H13: 18824500 | I13: PORR kadra
A14: 1.2 | B14: Remuneration TME | C14: 10232000 | D14: 10232000 | E14: 10232000 | F14: 10232000 | G14: 10232000 | H14: 10192900 | I14: TME kadra
C15: =SUM(C13:C14) -> 29056500 | D15: =SUM(D13:D14) -> 29056500 | E15: =SUM(E13:E14) -> 29056500 | F15: =SUM(F13:F14) -> 29056500 | G15: =SUM(G13:G14) -> 28713000 | H15: =SUM(H13:H14) -> 29017400
G16: =G15-$F15 -> -343500 | H16: =H15-$F15 -> -39100
A18: 2 | B18: EQUIPMENT | C18: =C23+C38+C45+C49+C58 -> 2404000 | D18: =D23+D38+D45+D49+D58 -> 2404000 | E18: =E23+E38+E45+E49+E58 -> 2404000 | F18: =F23+F38+F45+F49+F58 -> 2389000 | G18: =G23+G38+G45+G49+G58 -> 2419000.6 | H18: =H23+H38+H45+H49+H58 -> 2404100
G19: =G18-$F18 -> 30000.65 | H19: =H18-$F18 -> 15100.014
A21: 2.1 | B21: Safety and health protection | C21: 96000 | D21: 96000 | E21: 96000 | F21: 96000 | G21: 96000 | H21: 90866.46
A22: 2.1.1 | B22: Lunches ECD 53 / 53rev 1 | C22: 0 | D22: 0 | E22: 0 | F22: 0 | G22: 0 | H22: 5233.54 | I22: MICHELIN
C23: =SUM(C21:C22) -> 96000 | D23: =SUM(D21:D22) -> 96000 | E23: =SUM(E21:E22) -> 96000 | F23: =SUM(F21:F22) -> 96000 | G23: =SUM(G21:G22) -> 96000 | H23: =SUM(H21:H22) -> 96100
G24: =G23-$F23 -> 0 | H24: =H23-$F23 -> 100
A26: 2.2 | B26: Small equipment hire | C26: 90000 | D26: 89038 | E26: 84038 | F26: 55834 | G26: 48734 | H26: 43734
A27: 2.2.1 | B27: Rental of a crane for driving a shovel ECD 3 | C27: 0 | D27: 962 | E27: 962 | F27: 962 | G27: 962 | H27: 962 | I27: BUDIZOL | J27: 4502914407
A28: 2.2.2 | B28: Rental of ECD 15 (Świnoujście - Włocławek) | C28: 0 | D28: 0 | E28: 2500 | F28: 2500 | G28: 2500 | H28: 2500 | I28: SILOGOSTIC | J28: 4502946426
A29: 2.2.3 | B29: Rental of ECD 15 rev 1 (Rzeszów - Włocławek) | C29: 0 | D29: 0 | E29: 2500 | F29: 2500 | G29: 2500 | H29: 2500 | I29: SILOGOSTIC | J29: 4502946426
A30: 2.2.4 | B30: Rental of ECD 15 rev 2 (Świnoujście - Włocławek) | C30: 0 | D30: 0 | E30: 0 | F30: 2400 | G30: 2400 | H30: 2400 | I30: SILOGOSTIC | J30: 4502946426
A31: 2.2.5 | B31: Rental of ECD 15 rev 3 (Rzeszów - Włocławek) | C31: 0 | D31: 0 | E31: 0 | F31: 1400 | G31: 1400 | H31: 1400 | I31: SILOGOSTIC | J31: 4502946426
A32: 2.2.6 | B32: Rental of ECD 44 generators | C32: 0 | D32: 0 | E32: 0 | F32: 23904 | G32: 23904 | H32: 23904 | I32: MOBIL SERWIS | J32: 4503007260
A33: 2.2.7 | B33: Rental of ECD 15 rev 4 (Lublin - Włocławek) | C33: 0 | D33: 0 | E33: 0 | F33: 500 | G33: 500 | H33: 500 | I33: SILOGOSTIC | J33: 4502946426
A34: 2.2.8 | B34: Rental of a drainage pump ECD 49 | C34: 0 | D34: 0 | E34: 0 | F34: 0 | G34: 4600 | H34: 4600 | I34: KLAUDIA | J34: 4503061913
A35: 2.2.9 | B35: Rental of ECD 15 rev 5 (Świnoujście - Włocławek) | C35: 0 | D35: 0 | E35: 0 | F35: 0 | G35: 2500 | H35: 2500 | I35: SILOGOSTIC | J35: 4502946426
A36: 2.2.10 | B36: Transport - ECD56 | C36: 0 | D36: 0 | E36: 0 | F36: 0 | G36: 0 | H36: 2700 | I36: FROGTRANS | J36: 4503121690
A37: 2.2.11 | B37: Transport - ECD56 rev 1 | C37: 0 | D37: 0 | E37: 0 | F37: 0 | G37: 0 | H37: 2300 | I37: FROGTRANS | J37: 4503121690
C38: =SUM(C26:C35) -> 90000 | D38: =SUM(D26:D35) -> 90000 | E38: =SUM(E26:E35) -> 90000 | F38: =SUM(F26:F35) -> 90000 | G38: =SUM(G26:G37) -> 90000 | H38: =SUM(H26:H37) -> 90000
G39: =G38-$F38 -> 0 | H39: =H38-$F38 -> 0
A41: 2.3 | B41: 30 T Truck Crane | C41: 314000 | D41: 314000 | E41: 123833 | F41: 123832.99 | G41: 123833 | H41: 123833
A42: 2.3.1 | B42: Open order - small building materials ECD 18 | C42: 0 | D42: 0 | E42: 50000.004 | F42: 50000.003 | G42: 50000.643 | H42: 50000.001 | I42: MAT-BUD | J42: 4502950515
A43: 2.3.2 | B43: Open order - small building materials ECD 19 | C43: 0 | D43: 0 | E43: 49999.996 | F43: 49999.997 | G43: 49999.997 | H43: 50000.003 | I43: HURTOWNIA TOOLS | J43: 4502950551
A44: 2.3.3 | B44: ECR 8 stationary cranes | C44: 0 | D44: 0 | E44: 90167 | F44: 90167.004 | G44: 90167.004 | H44: 90167.004 | I44: ŻURAWIE WIELKOPOLSKIE
C45: =SUM(C41:C44) -> 314000 | D45: =SUM(D41:D44) -> 314000 | E45: =SUM(E41:E44) -> 314000 | F45: =SUM(F41:F44) -> 313999.99 | G45: =SUM(G41:G44) -> 314000.64 | H45: =SUM(H41:H44) -> 314000.01
G46: =G45-$F45 -> 0.65 | H46: =H45-$F45 -> 0.014482759
A48: 2.4 | B48: Manitou Charger | C48: 544000 | D48: 544000 | E48: 544000 | F48: 544000 | G48: 544000 | H48: 544000
...

Sheet 1_Design
C2: BUDGET APERTURA | D2: BUDGET 02 | E2: BUDGET 07 | F2: BUDGET 14 (B0 approvato Mar 26) | G2: BUDGET 17 | H2: BUDGET 19 | I2: ORDINATO | J2: DA ORDINARE EXTRA | K2: TOTALE CON FORECAST
C3: =C4+C30 -> 45590000 | D3: =D4+D30 -> 45590000 | E3: =E4+E30 -> 45990000 | K3: =K4+K30 -> 45590000 | M3: =SUM(M6:M9) -> 45590000
A4: 1 | B4: DESIGN | C4: =C13+C27 -> 27170000 | D4: =D13+D27 -> 27170000 | E4: =E13+E27 -> 27170000 | F4: =F13+F27 -> 27170000 | G4: =G13+G27 -> 27170000 | H4: =H13+H27 -> 27170000 | I4: =I13+I27+I33+I38+I42+I46 -> 0 | J4: =J13+J27+J33+J38+J42+J46 -> 0 | K4: =K13+K27 -> 27170000
G5: =G4-$F$4 -> 0.0052067265 | H5: =H4-$F$4 -> 0.0051454566 | K5: =K4-$F$4 -> 0.0051454566
L6: Ordered | M6: =H12+H17+H37+H26+H18+H20+H22+H24 -> 24886974
L7: Negotiation | M7: =H65+H16+H21+H25+H36 -> 17372026
D8: SAVINGS | E8: =D14+D34 -> 0 | F8: =E14+E34 -> 0 | G8: =F14+F34 -> 0 | H8: =G14+G34 -> -0.0033339988 | J8: SAVINGS | L8: Planned | M8: =H19+H23+H32+H41+H45+H49+H53+H57+H61 -> 3331000
D9: EXTRA | E9: =D47 -> 0 | F9: =E47 -> 0 | G9: =F47 -> 0 | H9: =G47 -> 0 | J9: EXTRA | L9: Extra | M9: =J4 -> 0
L10: (Buffer) | M10: =H16+H21+H25+H36 -> 372026
A12: 1.1 | B12: TME design | C12: 9890000 | D12: 9890000 | E12: 9890000 | F12: 9890000 | G12: 9890000 | H12: 9890000 | K12: =SUM(H12:J12) -> 9890000 | L12: TME
C13: =SUM(C12:C12) -> 9890000 | D13: =SUM(D12:D12) -> 9890000 | E13: =SUM(E12:E12) -> 9890000 | F13: =SUM(F12:F12) -> 9890000 | G13: =SUM(G12:G12) -> 9890000 | H13: =SUM(H12:H12) -> 9890000 | I13: =SUM(I12:I12) -> 0 | J13: =SUM(J12:J12) -> 0 | K13: =SUM(K12:K12) -> 9890000
G14: =$F13-G13 -> -0.0033339988 | H14: =$F13-H13 -> 0 | K14: =$F13-K13 -> 0
A16: 1.2 | B16: Detailed architectural, structural, sanitary and road designs | C16: 12200000 | D16: 100000 | E16: 100000 | F16: 100000 | G16: 100000 | H16: 100000 | K16: =SUM(H16:J16) -> 100000
A17: 1.2.1 | B17: Detailed architectural, structural, sanitary and road designs - ECR 1 | C17: 0 | D17: 12100000 | E17: 12100000 | F17: 12100000 | G17: 12100000 | H17: 12100000 | K17: =SUM(H17:J17) -> 12100000 | L17: FOROOM | M17: 4502938068
A18: 1.2.2 | B18: Detailed design: boiler support steel structure and equipment support structures - ECD 41 | C18: 500000 | D18: 500000 | E18: 500000 | F18: 500000 | G18: 500000 | H18: 500000 | K18: =SUM(H18:J18) -> 500000 | L18: ODS | M18: Ok
A19: 1.2.3 | B19: Detailed design: fire-fighting system | C19: 260000 | D19: 260000 | E19: 260000 | F19: 260000 | G19: 260000 | H19: 260000 | K19: =SUM(H19:J19) -> 260000
A20: 1.2.4 | B20: Electrical & I/C detailed design | C20: 1580000 | D20: 1580000 | E20: 1580000 | F20: 1580000 | G20: 1580000 | H20: 1580000 | K20: =SUM(H20:J20) -> 1580000 | L20: ELEKTROSERV - ZAP | M20: Ok
A21: 1.2.5 | B21: Building and detailed design of the GPO/GPZ station | C21: 440000 | D21: 50000 | E21: 50000 | F21: 50000 | G21: 50000 | H21: 50000 | K21: =SUM(H21:J21) -> 50000
A22: 1.2.5.1 | B22: Building and detailed design of the GPO/GPZ station | C22: 0 | D22: 390000 | E22: 390000 | F22: 390000 | G22: 390000 | H22: 390000 | K22: =SUM(H22:J22) -> 390000 | L22: MENOS | M22: Ok
A23: 1.2.6 | B23: Piping and ducts design | C23: 2000000 | D23: 2000000 | E23: 2000000 | F23: 2000000 | G23: 2000000 | H23: 1901000 | K23: =SUM(H23:J23) -> 1901000
A24: 1.2.6.1 | B24: Air and flue gas ducts design - ECR20 | C24: 0 | D24: 0 | E24: 0 | F24: 0 | G24: 0 | H24: 99000 | K24: =SUM(H24:J24) -> 99000 | L24: ODS | M24: 4502993588
A25: 1.2.7 | B25: Other documentation, opinions, agreements, permits, provisions, approvals and decisions necessary for the design, execution of the Works and commissioning of the investment (concession documentation for the generation of electricity and heat from a renewable energy source, ITPOE operating permit, integrated permit, geological designs and documentation, commissioning designs, operating instructions, etc.). | C25: 300000 | D25: 300000 | E25: 187000 | F25: 187000 | G25: 187000 | H25: 187000 | K25: =SUM(H25:J25) -> 187000
A26: 1.2.7.1 | B26: Preparation of the application for the issuance of an integrated permit with all necessary documents ECD 27 | C26: 0 | D26: 0 | E26: 113000 | F26: 113000 | G26: 113000 | H26: 113000 | K26: =SUM(H26:J26) -> 113000 | L26: ZAKŁAD SOZOTECHNIKI | M26: 4502966963
C27: =SUM(C16:C26) -> 17280000 | D27: =SUM(D16:D26) -> 17280000 | E27: =SUM(E16:E26) -> 17280000 | F27: =SUM(F16:F26) -> 17280000 | G27: =SUM(G16:G26) -> 17280000 | H27: =SUM(H16:H26) -> 17280000 | I27: =SUM(I16:I26) -> 0 | J27: =SUM(J16:J26) -> 0 | K27: =SUM(K16:K26) -> 17280000
G28: =$F27-G27 -> -0.0018727295 | H28: =$F27-H27 -> -0.0051454566 | K28: =$F27-K27 -> -0.0051454566
B30: Service companies | C30: =C33+C38+C42+C46+C50+C54+C58+C62+C66 -> 18420000 | D30: =D33+D38+D42+D46+D50+D54+D58+D62+D66 -> 18420000 | E30: =E33+E38+E42+E46+E50+E54+E58+E62+E66 -> 18820000 | F30: =F33+F38+F42+F46+F50+F54+F58+F62+F66 -> 18420000 | G30: =G33+G38+G42+G46+G50+G54+G58+G62+G66 -> 18420000 | H30: =H33+H38+H42+H46+H50+H54+H58+H62+H66 -> 18420000 | K30: =K33+K38+K42+K46+K50+K54+K58+K62+K66 -> 18420000
A32: 1.3 | B32: Noise Analysis and noise protection design | C32: 100000 | D32: 100000 | E32: 100000 | F32: 100000 | G32: 100000 | H32: 100000 | K32: =SUM(H32:J32) -> 100000
C33: =SUM(C32:C32) -> 100000 | D33: =SUM(D32:D32) -> 100000 | E33: =SUM(E32:E32) -> 100000 | F33: =SUM(F32:F32) -> 100000 | G33: =SUM(G32:G32) -> 100000 | H33: =SUM(H32:H32) -> 100000 | I33: =SUM(I32:I32) -> 0 | J33: =SUM(J32:J32) -> 0 | K33: =SUM(K32:K32) -> 100000
G34: =$F33-G33 -> 0 | H34: =$F33-H33 -> 0 | K34: =$F33-K33 -> 0
A36: 1.4 | B36: HAZOP study and SIL analysis | C36: 250000 | D36: 250000 | E36: 250000 | F36: 35026 | G36: 35026 | H36: 35026 | K36: =SUM(H36:J36) -> 35026
A37: 1.4.1 | B37: HAZOP study and SIL analysis | F37: 214974 | G37: 214974 | H37: 214974 | K37: =SUM(H37:J37) -> 214974 | L37: UDT CERT | M37: 4503027816
C38: =SUM(C36:C37) -> 250000 | D38: =SUM(D36:D37) -> 250000 | E38: =SUM(E36:E37) -> 250000 | F38: =SUM(F36:F37) -> 250000 | G38: =SUM(G36:G37) -> 250000 | H38: =SUM(H36:H37) -> 250000 | I38: =SUM(I36:I37) -> 0 | J38: =SUM(J36:J37) -> 0 | K38: =SUM(K36:K37) -> 250000
G39: =$F38-G38 -> 0 | H39: =$F38-H38 -> 0 | K39: =$F38-K38 -> 0
A41: 1.5 | B41: Fire safety instructions | C41: 100000 | D41: 100000 | E41: 100000 | F41: 100000 | G41: 100000 | H41: 100000 | K41: =SUM(H41:J41) -> 100000
C42: =SUM(C41:C41) -> 100000 | D42: =SUM(D41:D41) -> 100000 | E42: =SUM(E41:E41) -> 100000 | F42: =SUM(F41:F41) -> 100000 | G42: =SUM(G41:G41) -> 100000 | H42: =SUM(H41:H41) -> 100000 | I42: =SUM(I41:I41) -> 0 | J42: =SUM(J41:J41) -> 0 | K42: =SUM(K41:K41) -> 100000
G43: =$F42-G42 -> 0 | H43: =$F42-H42 -> 0 | K43: =$F42-K42 -> 0
A45: 1.6 | B45: Explosion hazard assessment | C45: 120000 | D45: 120000 | E45: 120000 | F45: 120000 | G45: 120000 | H45: 120000 | K45: =SUM(H45:J45) -> 120000
C46: =SUM(C45:C45) -> 120000 | D46: =SUM(D45:D45) -> 120000 | E46: =SUM(E45:E45) -> 120000 | F46: =SUM(F45:F45) -> 120000 | G46: =SUM(G45:G45) -> 120000 | H46: =SUM(H45:H45) -> 120000 | I46: =SUM(I45:I45) -> 0 | J46: =SUM(J45:J45) -> 0 | K46: =SUM(K45:K45) -> 120000
G47: =$F46-G46 -> 0 | H47: =$F46-H46 -> 0 | K47: =$F46-K46 -> 0
A49: 1.7 | B49: Technical Consultant for certification and for complying with European Directives | C49: 100000 | D49: 100000 | E49: 100000 | F49: 100000 | G49: 100000 | H49: 100000.01 | K49: =SUM(H49:J49) -> 100000.01
...

Sheet 2_Civil Work
C2: BUDGET APERTURA | D2: BUDGET 02 | E2: BUDGET 07 | F2: BUDGET 14 (B0 approvato Mar 26) | G2: BUDGET 17 | H2: BUDGET 19 | I2: ORDINATO | J2: DA ORDINARE EXTRA | K2: TOTALE CON FORECAST | M2: =SUM(M5:M8) -> 1.0810977e+08
A3: 2 | B3: CIVIL WORKS | C3: =C16+C23+C29+C38+C64+C76+C80+C97+C107+C111+C133+C139+C143+C152+C156+C162 -> 112409767 | D3: =D16+D23+D29+D38+D64+D76+D80+D97+D107+D111+D133+D139+D143+D152+D156+D162 -> 1.1240977e+08 | E3: =E16+E23+E29+E38+E64+E76+E80+E97+E107+E111+E133+E139+E143+E152+E156+E162 -> 1.1240977e+08 | F3: =F16+F23+F29+F38+F64+F76+F80+F97+F107+F111+F133+F139+F143+F152+F156+F162 -> 1.0810977e+08 | G3: =G16+G23+G29+G38+G64+G76+G80+G97+G107+G111+G133+G139+G143+G152+G156+G162 -> 1.0810977e+08 | H3: =H16+H23+H29+H38+H64+H76+H80+H97+H107+H111+H133+H139+H143+H152+H156+H162 -> 1.0810977e+08 | I3: =I16+I23+I29+I38+I64+I76+I80+I97+I107+I111+I133+I139+I143+I152+I156+I162 -> 0 | J3: =J16+J23+J29+J38+J64+J76+J80+J97+J107+J111+J133+J139+J143+J152+J156+J162 -> 0 | K3: =K16+K23+K29+K38+K64+K76+K80+K97+K107+K111+K133+K139+K143+K152+K156+K162 -> 1.0810977e+08
G4: =G3-$F$3 -> 0.0033721477 | H4: =H3-$F$3 -> 0.0055060089 | K4: =K3-$F$3 -> 0.0055060089
L5: Ordered | M5: =H13+H14+H15+H20+H21+H27+H28+H34+H35+H36+H37+H44+H45+H47+H49+H50+H54+H57+H59+H60+H61+H70+H72+H75+H121++H123+H150+H149+H69 -> 53496524 | N5: =G15+G20+G21+G22+G27+G34+G35+G36+G44+G47+G49+G50+G54+G57+G59+G60+G61+G69+G70+G72+G75+G121+G123+G149+G150 -> 53701520
L6: Negotiation + buffer | M6: =H12+H33+H42+H43+H46+H48+H53+H56+H68+H71+H74+H120+H122+H148+H22 -> 16378807
D7: SAVINGS | J7: SAVINGS | L7: Planned | M7: =H26+H32+H62+H63+H55+H73+H79+H84+H85+H86+H87+H88+H89+H90+H91+H92+H93+H94+H95+H96+H102+H101+H103+H104+H105+H106+H110+H115+H116+H117+H118+H119+H124+H125+H126+H127+H128+H129+H130+H131+H132+H137+H138+H142+G1445+H151+H155+H160+H161+H147 -> 38234436
D8: EXTRA | J8: EXTRA | L8: Extra | M8: =SUM(I3:J3) -> 0
L9: (Buffer) | M9: =H42+H43+H46+H53+H120+H12+H33+H48+H56+H122+H68+H71+H74+H148+H22 -> 16378807
A11: 2.1 | B11: Foundation works | C11: 4613087 | D11: 0 | E11: 0 | F11: 0 | G11: 0 | H11: 0 | K11: =SUM(H11:J11) -> 0
A12: 2.1.1 | B12: Buffer | C12: 0 | D12: 1113087 | E12: 313087 | F12: 229887 | G12: 229887 | H12: 229887 | K12: =SUM(H12:J12) -> 229887
A13: 2.1.2 | B13: Diaphragm wall and barrettes part 1 | C13: 0 | D13: 3500000 | E13: 3176000 | F13: 0 | G13: 0 | H13: 0 | K13: =SUM(H13:J13) -> 0 | L13: Stump-Franki Sp. z o.o.
A14: 2.1.3 | B14: Barrettes part 2 | C14: 0 | D14: 0 | E14: 1124000 | F14: 0 | G14: 0 | H14: 0 | K14: =SUM(H14:J14) -> 0 | L14: Stump-Franki Sp. z o.o.
A15: 2.1.4 | B15: Concrete rubble ECD 45 | C15: 0 | D15: 0 | E15: 0 | F15: 83200 | G15: 83200 | H15: 83200 | K15: =SUM(H15:J15) -> 83200 | L15: Usługi Sprzętowo - Transportowe Sławomir Boruczkowski
C16: =SUM(C11:C15) -> 4613087 | D16: =SUM(D11:D15) -> 4613087 | E16: =SUM(E11:E15) -> 4613087 | F16: =SUM(F11:F15) -> 313087 | G16: =SUM(G11:G15) -> 313087 | H16: =SUM(H11:H15) -> 313087 | I16: =SUM(I11:I15) -> 0 | J16: =SUM(J11:J15) -> 0 | K16: =SUM(K11:K15) -> 313087
G17: =$F16-G16 -> 0 | H17: =$F16-H16 -> 0 | K17: =$F16-K16 -> 0
A19: 2.2 | B19: Earthworks | C19: 0 | D19: 0 | E19: 0 | F19: 0 | G19: 0 | H19: 0 | K19: =SUM(H19:J19) -> 0
A20: 2.2.1 | B20: ECR 3 / ECR 3 rev 1 working platform | C20: 176673 | D20: 176673 | E20: 176673 | F20: 176673 | G20: 176673 | H20: 176673 | K20: =SUM(H20:J20) -> 176673 | L20: MAR-KOP Marcin Mierzwa | M20: 4502939064
A21: 2.2.2 | B21: Earthmoving robots ECR 3 / ECR 3 rev 1 | C21: 2196542 | D21: 2196542 | E21: 2196542 | F21: 2196542 | G21: 2196542 | H21: 2196542 | K21: =SUM(H21:J21) -> 2196542 | L21: MAR-KOP Marcin Mierzwa | M21: 4502939064
A22: 2.2.3 | B22: Earthworks - backfill of retaining wall ECR 3 / ECR rev 1 | C22: 313419 | D22: 313419 | E22: 313419 | F22: 313419 | G22: 313419 | H22: 313419 | K22: =SUM(H22:J22) -> 313419
C23: =SUM(C19:C22) -> 2686634 | D23: =SUM(D19:D22) -> 2686634 | E23: =SUM(E19:E22) -> 2686634 | F23: =SUM(F19:F22) -> 2686634 | G23: =SUM(G19:G22) -> 2686634 | H23: =SUM(H19:H22) -> 2686634 | I23: =SUM(I19:I22) -> 0 | J23: =SUM(J19:J22) -> 0 | K23: =SUM(K19:K22) -> 2686634
G24: =$F23-G23 -> 0 | H24: =$F23-H23 -> 0 | K24: =$F23-K23 -> 0
A26: 2.3 | B26: Drainage | C26: 437599 | D26: 437599 | E26: 437599 | F26: 437599 | G26: 367599 | H26: 332599 | K26: =SUM(H26:J26) -> 332599
A27: 2.3.1 | B27: Dehydration ECD 50 | C27: 0 | D27: 0 | E27: 0 | F27: 0 | G27: 70000 | H27: 70000 | K27: =SUM(H27:J27) -> 70000 | L27: HAMER | M27: 4503066286
A28: 2.3.1 | B28: Dehydration ECD 50 rev 1 | C28: 0 | D28: 0 | E28: 0 | F28: 0 | G28: 0 | H28: 35000 | K28: =SUM(H28:J28) -> 35000 | L28: HAMER | M28: 4503066286
C29: =SUM(C26:C28) -> 437599 | D29: =SUM(D26:D28) -> 437599 | E29: =SUM(E26:E28) -> 437599 | F29: =SUM(F26:F28) -> 437599 | G29: =SUM(G26:G28) -> 437599 | H29: =SUM(H26:H28) -> 437599 | I29: =SUM(I26:I28) -> 0 | J29: =SUM(J26:J28) -> 0 | K29: =SUM(K26:K28) -> 437599
G30: =$F29-G29 -> -0.0028571429 | H30: =$F29-H29 -> -0.0028571429 | K30: =$F29-K29 -> -0.0028571429
A32: 2.4 | B32: Insulation | C32: 1138973 | D32: 1138973 | E32: 1138973 | F32: 403973 | G32: 345021 | H32: 298038 | K32: =SUM(H32:J32) -> 298038
A33: 2.4.1 | C33: 0 | D33: 0 | E33: 0 | F33: 1953.86 | G33: 1953.85 | H33: 1953.85 | K33: =SUM(H33:J33) -> 1953.85
A34: 2.4.1 | B34: ECR 11 reinforced concrete works | C34: 0 | D34: 0 | E34: 0 | F34: 733046.15 | G34: 733046.15 | H34: 733046.15 | K34: =SUM(H34:J34) -> 733046.15 | L34: AF KONSTRUKCJE | M34: 4502997466
A35: 2.4.2 | B35: Waterproofing ECD 51 | C35: 0 | D35: 0 | E35: 0 | F35: 0 | G35: 31352 | H35: 31352 | K35: =SUM(H35:J35) -> 31352 | L35: TWS | M35: 4503071267
A36: 2.4.3 | B36: Foundation insulation materials ECD 14 rev 3 | C36: 0 | D36: 0 | E36: 0 | F36: 0 | G36: 27600 | H36: 27600 | K36: =SUM(H36:J36) -> 27600 | L36: MAT-BUD | M36: 4502934293
A37: 2.4.4 | B37: Waterproofing - ECD 51 rev 1 | C37: 0 | D37: 0 | E37: 0 | F37: 0 | G37: 0 | H37: 46983 | K37: =SUM(H37:J37) -> 46983 | L37: TWS | M37: 4503071267
C38: =SUM(C32:C37) -> 1138973 | D38: =SUM(D32:D37) -> 1138973 | E38: =SUM(E32:E37) -> 1138973 | F38: =SUM(F32:F37) -> 1138973 | G38: =SUM(G32:G37) -> 1138973 | H38: =SUM(H32:H37) -> 1138973 | I38: =SUM(I32:I37) -> 0 | J38: =SUM(J32:J37) -> 0 | K38: =SUM(K32:K37) -> 1138973
G39: =$F38-G38 -> 0.01 | H39: =$F38-H38 -> 0.01 | K39: =$F38-K38 -> 0.01
A41: 2.5 | B41: Reinforced concrete structure | C41: 0 | D41: 0 | E41: 0 | F41: 0 | G41: 0 | H41: 0 | K41: =SUM(H41:J41) -> 0
A42: 2.5.1 | B42: Reinforced concrete foundation structure | C42: 16024473 | D42: 14169473 | E42: 10617413 | F42: 5117413.3 | G42: 5117413.3 | H42: 5117413.3 | K42: =SUM(H42:J42) -> 5117413.3
A43: 2.5.1.1 | B43: Supply of reinforcing steel | C43: 0 | D43: 33680.7 | E43: 33680.7 | F43: 33680.7 | G43: 33680.7 | H43: 7240.7 | K43: =SUM(H43:J43) -> 7240.7
A44: 2.5.1.1.1 | B44: Supply of ECR 2 reinforcing steel | C44: 0 | D44: 1821319 | E44: 1821319 | F44: 1821319 | G44: 1821319 | H44: 1821319 | K44: =SUM(H44:J44) -> 1821319 | L44: THYSSENKRUPP MATERIALS POLAND S.A. | M44: 4502938804
A45: 2.5.1.1.2 | B45: Reinforced meches - ECD 14 rev 4 | C45: 0 | D45: 0 | E45: 0 | F45: 0 | G45: 0 | H45: 26440 | K45: =SUM(H45:J45) -> 26440 | L45: MAT-BUD | M45: 4502934293
A46: 2.5.1.1.2 | B46: Concrete testing | C46: 0 | D46: 0 | E46: 500 | F46: 500 | G46: 500 | H46: 500 | K46: =SUM(H46:J46) -> 500
...

Sheet 3_Electrical Works
C2: BUDGET APERTURA | D2: BUDGET 02 | E2: BUDGET 07 | F2: BUDGET 14 (B0 approvato Mar 26) | G2: BUDGET 17 | H2: BUDGET 19 | I2: ORDINATO | J2: DA ORDINARE EXTRA | K2: TOTALE CON FORECAST | M2: =SUM(M5:M8) -> 58345340
A3: 3 | B3: ELECTRICAL WORKS | C3: =C18+C23+C27+C35 -> 58345340 | D3: =D18+D23+D27+D35 -> 58345340 | E3: =E18+E23+E27+E35 -> 58345340 | F3: =F18+F23+F27+F35 -> 58345340 | G3: =G18+G23+G27+G35 -> 58345340 | H3: =H18+H23+H27+H35 -> 58345340 | I3: =I18+I23+I27+I35 -> 0 | J3: =J18+J23+J27+J35 -> 0 | K3: =K18+K23+K27+K35 -> 58345340
G4: =$F$3-G3 -> 0 | H4: =$F$3-H3 -> 0 | K4: =$F$3-K3 -> 0
L5: Ordered | M5: =H13+H22+H32 -> 36070000
L6: Negotiation + Buffer | M6: =H12+H31 -> 2016200
D7: SAVINGS | L7: Planned | M7: =H15+H14+H16+H17+H26+H33+H34 -> 20259140
D8: EXTRA | L8: Extra | M8: =SUM(I3:J3) -> 0
L9: (Buffer) | M9: =H12+H31 -> 2016200
A11: 3.1 | B11: Electrical installation | C11: 0 | D11: 0 | E11: 0 | F11: 0 | G11: 0 | H11: 0 | K11: =SUM(H11:J11) -> 0
A12: 3.1.1 | B12: Delivery and installation of electrical equipment | C12: 29982000 | D12: 29982000 | E12: 1700000 | F12: 1700000 | G12: 1700000 | H12: 1700000 | K12: =SUM(H12:J12) -> 1700000
A13: 3.1.1.1 | B13: Delivery and installation of electrical equipment | C13: 0 | D13: 0 | E13: 28282000 | F13: 28282000 | G13: 28282000 | H13: 28282000 | K13: =SUM(H13:J13) -> 28282000 | L13: ELEKTROSERV - ZAP | M13: ok
A14: 3.1.2 | B14: Electrical heat treacing of piping - hot part | C14: 742140 | D14: 742140 | E14: 742140 | F14: 742140 | G14: 742140 | H14: 742140 | K14: =SUM(H14:J14) -> 742140
A15: 3.1.3 | B15: Aviation warning lights | C15: 140000 | D15: 140000 | E15: 140000 | F15: 140000 | G15: 140000 | H15: 140000 | K15: =SUM(H15:J15) -> 140000
A16: 3.1.4 | B16: Fire detection and alarm system ( electrical&teletechnical part ) | C16: 980000 | D16: 980000 | E16: 980000 | F16: 980000 | G16: 980000 | H16: 980000 | K16: =SUM(H16:J16) -> 980000
A17: 3.1.5 | B17: Smoke extraction from waste bunker and tipping hall (electrical&teletechnical part ) | C17: 175000 | D17: 175000 | E17: 175000 | F17: 175000 | G17: 175000 | H17: 175000 | K17: =SUM(H17:J17) -> 175000
C18: =SUM(C11:C17) -> 32019140 | D18: =SUM(D11:D17) -> 32019140 | E18: =SUM(E11:E17) -> 32019140 | F18: =SUM(F11:F17) -> 32019140 | G18: =SUM(G11:G17) -> 32019140 | H18: =SUM(H11:H17) -> 32019140 | I18: =SUM(I11:I17) -> 0 | J18: =SUM(J11:J17) -> 0 | K18: =SUM(K11:K17) -> 32019140
G19: =$F18-G18 -> 0 | H19: =$F18-H18 -> 0 | K19: =$F18-K18 -> 0
A21: 3.2 | B21: Teletechnical installations | C21: 2579200 | D21: 0 | E21: 0 | F21: 0 | G21: 0 | H21: 0 | K21: =SUM(H21:J21) -> 0
A22: 3.2.1 | B22: Teletechnical installations | C22: 0 | D22: 2579200 | E22: 2579200 | F22: 2579200 | G22: 2579200 | H22: 2579200 | K22: =SUM(H22:J22) -> 2579200 | L22: ELEKTROSERV - ZAP | M22: ok
C23: =SUM(C21:C22) -> 2579200 | D23: =SUM(D21:D22) -> 2579200 | E23: =SUM(E21:E22) -> 2579200 | F23: =SUM(F21:F22) -> 2579200 | G23: =SUM(G21:G22) -> 2579200 | H23: =SUM(H21:H22) -> 2579200 | I23: =SUM(I21:I22) -> 0 | J23: =SUM(J21:J22) -> 0 | K23: =SUM(K21:K22) -> 2579200
G24: =$F23-G23 -> 0 | H24: =$F23-H23 -> 0 | K24: =$F23-K23 -> 0
A26: 3.3 | B26: GPO/GPZ power supply | C26: 13510000 | D26: 13510000 | E26: 13510000 | F26: 13510000 | G26: 13510000 | H26: 13510000 | K26: =SUM(H26:J26) -> 13510000
C27: =SUM(C26:C26) -> 13510000 | D27: =SUM(D26:D26) -> 13510000 | E27: =SUM(E26:E26) -> 13510000 | F27: =SUM(F26:F26) -> 13510000 | G27: =SUM(G26:G26) -> 13510000 | H27: =SUM(H26:H26) -> 13510000 | I27: =SUM(I26:I26) -> 0 | J27: =SUM(J26:J26) -> 0 | K27: =SUM(K26:K26) -> 13510000
G28: =$F27-G27 -> 0 | H28: =$F27-H27 -> 0 | K28: =$F27-K27 -> 0
A30: 3.3 | B30: I&C works | C30: 0 | D30: 0 | E30: 0 | F30: 0 | G30: 0 | H30: 0 | K30: =SUM(H30:J30) -> 0
A31: 3.4.1 | B31: Automation system and instrumentation, communication networks and control room devices | C31: 5525000 | D31: 686200 | E31: 316200 | F31: 316200 | G31: 316200 | H31: 316200 | K31: =SUM(H31:J31) -> 316200
A32: 3.4.1.1 | B32: Automation system and instrumentation, communication networks and control room devices | C32: 0 | D32: 4838800 | E32: 5208800 | F32: 5208800 | G32: 5208800 | H32: 5208800 | K32: =SUM(H32:J32) -> 5208800 | L32: ELEKTROSERV - ZAP | M32: ok
A33: 3.4.2 | B33: DCS System | C33: 2752000 | D33: 2752000 | E33: 2752000 | F33: 2752000 | G33: 2752000 | H33: 2752000 | K33: =SUM(H33:J33) -> 2752000
A34: 3.4.3 | B34: Emission monitoring system (CEMS) | C34: 1960000 | D34: 1960000 | E34: 1960000 | F34: 1960000 | G34: 1960000 | H34: 1960000 | K34: =SUM(H34:J34) -> 1960000
C35: =SUM(C30:C34) -> 10237000 | D35: =SUM(D30:D34) -> 10237000 | E35: =SUM(E30:E34) -> 10237000 | F35: =SUM(F30:F34) -> 10237000 | G35: =SUM(G30:G34) -> 10237000 | H35: =SUM(H30:H34) -> 10237000 | I35: =SUM(I30:I34) -> 0 | J35: =SUM(J30:J34) -> 0 | K35: =SUM(K30:K34) -> 10237000
G36: =$F35-G35 -> 0 | H36: =$F35-H35 -> 0 | K36: =$F35-K35 -> 0

Sheet 4_Sanitary works and FF
C2: BUDHET APERTURA | D2: BUDHET 02 | E2: BUDHET 07 | F2: BUDHET 14 (B0 approvato Mar 26) | G2: BUDGET 17 | H2: BUDGET 19 | I2: ORDINATO | J2: DA ORDINARE EXTRA | K2: TOTALE CON FORECAST | M2: =SUM(M6:M9) -> 21293319
A3: 4 | B3: SANITARY WORKS AND FIRE-FIHHTINH SYSTEM | C3: =C13+C27+C40 -> 21293319 | D3: =D13+D27+D40 -> 21293319 | E3: =E13+E27+E40 -> 21293319 | F3: =F13+F27+F40 -> 21293319 | G3: =H13+H27+H40 -> 21293319 | H3: =H13+H27+H40 -> 21293319 | I3: =I13+I27+I40 -> 0 | J3: =J13+J27+J40 -> 0 | K3: =K13+K27+K40 -> 21293319
G4: =$F$3-H3 -> 0 | H4: =$F$3-H3 -> 0 | K4: =$F$3-K3 -> 0
L6: Ordered | M6: 0
D7: SAVINH | J7: SAVINH | L7: NeHotiation | M7: =0 -> 0
D8: EXTRA | J8: EXTRA | L8: Planned | M8: =H12+H17+H18+H19+H20+H21+H22+H23+H24+H25+H26+H31+H32+H33+H34+H35+H36+H37+H38+H39 -> 21293319
K9: =K7+K8 -> 0 | L9: Extra | M9: 0
L10: (Buffer) | M10: 0
A12: 4.1 | B12: Deodorization system | C12: 1009700 | D12: 1009700 | E12: 1009700 | F12: 1009700 | G12: 1009700 | H12: 1009700 | K12: =SUM(H12:J12) -> 1009700
C13: =SUM(C12:C12) -> 1009700 | D13: =SUM(D12:D12) -> 1009700 | E13: =SUM(E12:E12) -> 1009700 | F13: =SUM(F12:F12) -> 1009700 | G13: =SUM(H12:H12) -> 1009700 | H13: =SUM(H12:H12) -> 1009700 | I13: =SUM(I12:I12) -> 0 | J13: =SUM(J12:J12) -> 0 | K13: =SUM(K12:K12) -> 1009700
G14: =$F13-H13 -> 0 | H14: =$F13-H13 -> 0 | K14: =$F13-K13 -> 0
A16: 4.2 | B16: FirefiHhtinH system | C16: 0 | D16: 0 | E16: 0 | F16: 0 | G16: 0 | H16: 0 | K16: =SUM(H16:J16) -> 0
A17: 4.2.1 | B17: Fire detection and alarm system | C17: 2211870 | D17: 2211870 | E17: 2211870 | F17: 2211870 | G17: 2211870 | H17: 2211870 | K17: =SUM(H17:J17) -> 2211870
A18: 4.2.2 | B18: FirefiHhtinH water tank | C18: 275700 | D18: 275700 | E18: 275700 | F18: 275700 | G18: 275700 | H18: 275700 | K18: =SUM(H18:J18) -> 275700
A19: 4.2.3 | B19: FirefiHhtinH water pumpinH | C19: 715920 | D19: 715920 | E19: 715920 | F19: 715920 | G19: 715920 | H19: 715920 | K19: =SUM(H19:J19) -> 715920
A20: 4.2.4 | B20: FirefiHhtinH water external distribution, hoses, sprinklers | C20: 821016 | D20: 821016 | E20: 821016 | F20: 821016 | G20: 821016 | H20: 821016 | K20: =SUM(H20:J20) -> 821016
A21: 4.2.5 | B21: Installation of internal hydrants in buildinHs B1 and B2 | C21: 240990 | D21: 240990 | E21: 240990 | F21: 240990 | G21: 240990 | H21: 240990 | K21: =SUM(H21:J21) -> 240990
